<?xml version="1.0" encoding="UTF-8"?>
<robot name="rbkairos">
  <joint name="back_left_roller10_joint" type="continuous">
    <origin xyz="0. -0. -0.107" rpy="0.7853982 -1.5707963 0. "/>
    <parent link="summit_xl_back_left_wheel_link"/>
    <child link="back_left_roller10_link"/>
    <axis xyz="0. 0. 1."/>
  </joint>
  <joint name="back_left_roller11_joint" type="continuous">
    <origin xyz="0.0535 -0. -0.0926647" rpy="-0.0439603 1.2045692 0.8038372"/>
    <parent link="summit_xl_back_left_wheel_link"/>
    <child link="back_left_roller11_link"/>
    <axis xyz="0. 0. 1."/>
  </joint>
  <joint name="back_left_roller12_joint" type="continuous">
    <origin xyz="0.0926647 -0. -0.0535 " rpy="-0.5359965 0.7778994 0.3978639"/>
    <parent link="summit_xl_back_left_wheel_link"/>
    <child link="back_left_roller12_link"/>
    <axis xyz="0. 0. 1."/>
  </joint>
  <joint name="back_left_roller1_joint" type="continuous">
    <origin xyz="0.107 -0. 0. " rpy="-0.7853984 0. 0. "/>
    <parent link="summit_xl_back_left_wheel_link"/>
    <child link="back_left_roller1_link"/>
    <axis xyz="0. 0. 1."/>
  </joint>
  <joint name="back_left_roller2_joint" type="continuous">
    <origin xyz="0.0926647 -0. 0.0535 " rpy="-0.5359965 -0.7778994 -0.3978639"/>
    <parent link="summit_xl_back_left_wheel_link"/>
    <child link="back_left_roller2_link"/>
    <axis xyz="0. 0. 1."/>
  </joint>
  <joint name="back_left_roller3_joint" type="continuous">
    <origin xyz="0.0535 -0. 0.0926647" rpy="-0.0439603 -1.2045692 -0.8038372"/>
    <parent link="summit_xl_back_left_wheel_link"/>
    <child link="back_left_roller3_link"/>
    <axis xyz="0. 0. 1."/>
  </joint>
  <joint name="back_left_roller4_joint" type="continuous">
    <origin xyz="0. -0. 0.107" rpy="-0.7853982 -1.5707963 0. "/>
    <parent link="summit_xl_back_left_wheel_link"/>
    <child link="back_left_roller4_link"/>
    <axis xyz="0. 0. 1."/>
  </joint>
  <joint name="back_left_roller5_joint" type="continuous">
    <origin xyz="-0.0535 -0. 0.0926647" rpy="0.0275167 1.1863147 -0.8346186"/>
    <parent link="summit_xl_back_left_wheel_link"/>
    <child link="back_left_roller5_link"/>
    <axis xyz="0. 0. 1."/>
  </joint>
  <joint name="back_left_roller6_joint" type="continuous">
    <origin xyz="-0.0926647 -0. 0.0535 " rpy="0.5052382 0.7423047 -0.4450063"/>
    <parent link="summit_xl_back_left_wheel_link"/>
    <child link="back_left_roller6_link"/>
    <axis xyz="0. 0. 1."/>
  </joint>
  <joint name="back_left_roller7_joint" type="continuous">
    <origin xyz="-0.107 -0. 0. " rpy="0.7853984 0. 0. "/>
    <parent link="summit_xl_back_left_wheel_link"/>
    <child link="back_left_roller7_link"/>
    <axis xyz="0. 0. 1."/>
  </joint>
  <joint name="back_left_roller8_joint" type="continuous">
    <origin xyz="-0.0926647 -0. -0.0535 " rpy="0.523674 -0.7990885 0.3802593"/>
    <parent link="summit_xl_back_left_wheel_link"/>
    <child link="back_left_roller8_link"/>
    <axis xyz="0. 0. 1."/>
  </joint>
  <joint name="back_left_roller9_joint" type="continuous">
    <origin xyz="-0.0535 -0. -0.0926647" rpy="0.0789182 -1.2169379 0.7711197"/>
    <parent link="summit_xl_back_left_wheel_link"/>
    <child link="back_left_roller9_link"/>
    <axis xyz="0. 0. 1."/>
  </joint>
  <joint name="back_right_roller10_joint" type="continuous">
    <origin xyz="0. 0. -0.107" rpy="-0.7853982 -1.5707963 0. "/>
    <parent link="summit_xl_back_right_wheel_link"/>
    <child link="back_right_roller10_link"/>
    <axis xyz="0. 0. 1."/>
  </joint>
  <joint name="back_right_roller11_joint" type="continuous">
    <origin xyz="0.0535 0. -0.0926647" rpy="0.0112194 1.1918175 -0.8343325"/>
    <parent link="summit_xl_back_right_wheel_link"/>
    <child link="back_right_roller11_link"/>
    <axis xyz="0. 0. 1."/>
  </joint>
  <joint name="back_right_roller12_joint" type="continuous">
    <origin xyz="0.0926647 0. -0.0535 " rpy="0.5422567 0.7673631 -0.4066663"/>
    <parent link="summit_xl_back_right_wheel_link"/>
    <child link="back_right_roller12_link"/>
    <axis xyz="0. 0. 1."/>
  </joint>
  <joint name="back_right_roller1_joint" type="continuous">
    <origin xyz="0.107 0. 0. " rpy="0.7853984 0. 0. "/>
    <parent link="summit_xl_back_right_wheel_link"/>
    <child link="back_right_roller1_link"/>
    <axis xyz="0. 0. 1."/>
  </joint>
  <joint name="back_right_roller2_joint" type="continuous">
    <origin xyz="0.0926647 0. 0.0535 " rpy="0.5422567 -0.7673631 0.4066663"/>
    <parent link="summit_xl_back_right_wheel_link"/>
    <child link="back_right_roller2_link"/>
    <axis xyz="0. 0. 1."/>
  </joint>
  <joint name="back_right_roller3_joint" type="continuous">
    <origin xyz="0.0535 0. 0.0926647" rpy="0.0789182 -1.2169379 0.7711197"/>
    <parent link="summit_xl_back_right_wheel_link"/>
    <child link="back_right_roller3_link"/>
    <axis xyz="0. 0. 1."/>
  </joint>
  <joint name="back_right_roller4_joint" type="continuous">
    <origin xyz="0. 0. 0.107" rpy="0.7853982 -1.5707963 0. "/>
    <parent link="summit_xl_back_right_wheel_link"/>
    <child link="back_right_roller4_link"/>
    <axis xyz="0. 0. 1."/>
  </joint>
  <joint name="back_right_roller5_joint" type="continuous">
    <origin xyz="-0.0535 0. 0.0926647" rpy="0.0027539 1.1732169 0.8626051"/>
    <parent link="summit_xl_back_right_wheel_link"/>
    <child link="back_right_roller5_link"/>
    <axis xyz="0. 0. 1."/>
  </joint>
  <joint name="back_right_roller6_joint" type="continuous">
    <origin xyz="-0.0926647 0. 0.0535 " rpy="-0.5422567 0.7673631 0.4066663"/>
    <parent link="summit_xl_back_right_wheel_link"/>
    <child link="back_right_roller6_link"/>
    <axis xyz="0. 0. 1."/>
  </joint>
  <joint name="back_right_roller7_joint" type="continuous">
    <origin xyz="-0.107 0. 0. " rpy="-0.7853984 0. 0. "/>
    <parent link="summit_xl_back_right_wheel_link"/>
    <child link="back_right_roller7_link"/>
    <axis xyz="0. 0. 1."/>
  </joint>
  <joint name="back_right_roller8_joint" type="continuous">
    <origin xyz="-0.0926647 0. -0.0535 " rpy="-0.5422567 -0.7673631 -0.4066663"/>
    <parent link="summit_xl_back_right_wheel_link"/>
    <child link="back_right_roller8_link"/>
    <axis xyz="0. 0. 1."/>
  </joint>
  <joint name="back_right_roller9_joint" type="continuous">
    <origin xyz="-0.0535 0. -0.0926647" rpy="-0.0439603 -1.2045692 -0.8038372"/>
    <parent link="summit_xl_back_right_wheel_link"/>
    <child link="back_right_roller9_link"/>
    <axis xyz="0. 0. 1."/>
  </joint>
  <joint name="front_left_roller10_joint" type="continuous">
    <origin xyz="-0. -0. -0.107" rpy="-0.7853982 -1.5707963 0. "/>
    <parent link="summit_xl_front_left_wheel_link"/>
    <child link="front_left_roller10_link"/>
    <axis xyz="0. 0. 1."/>
  </joint>
  <joint name="front_left_roller11_joint" type="continuous">
    <origin xyz="0.0535 -0. -0.0926647" rpy="0.0597851 1.1990727 -0.8046284"/>
    <parent link="summit_xl_front_left_wheel_link"/>
    <child link="front_left_roller11_link"/>
    <axis xyz="0. 0. 1."/>
  </joint>
  <joint name="front_left_roller12_joint" type="continuous">
    <origin xyz="0.0926647 -0. -0.0535 " rpy="0.5201338 0.7603366 -0.4219694"/>
    <parent link="summit_xl_front_left_wheel_link"/>
    <child link="front_left_roller12_link"/>
    <axis xyz="0. 0. 1."/>
  </joint>
  <joint name="front_left_roller1_joint" type="continuous">
    <origin xyz="0.107 -0. 0. " rpy="0.7853984 0. 0. "/>
    <parent link="summit_xl_front_left_wheel_link"/>
    <child link="front_left_roller1_link"/>
    <axis xyz="0. 0. 1."/>
  </joint>
  <joint name="front_left_roller2_joint" type="continuous">
    <origin xyz="0.0926647 -0. 0.0535 " rpy="0.5359965 -0.7778994 0.3978639"/>
    <parent link="summit_xl_front_left_wheel_link"/>
    <child link="front_left_roller2_link"/>
    <axis xyz="0. 0. 1."/>
  </joint>
  <joint name="front_left_roller3_joint" type="continuous">
    <origin xyz="0.0535 -0. 0.0926647" rpy="0.0439603 -1.2045692 0.8038372"/>
    <parent link="summit_xl_front_left_wheel_link"/>
    <child link="front_left_roller3_link"/>
    <axis xyz="0. 0. 1."/>
  </joint>
  <joint name="front_left_roller4_joint" type="continuous">
    <origin xyz="-0. -0. 0.107" rpy="0.7853982 -1.5707963 0. "/>
    <parent link="summit_xl_front_left_wheel_link"/>
    <child link="front_left_roller4_link"/>
    <axis xyz="0. 0. 1."/>
  </joint>
  <joint name="front_left_roller5_joint" type="continuous">
    <origin xyz="-0.0535 -0. 0.0926647" rpy="-0.0439603 1.2045692 0.8038372"/>
    <parent link="summit_xl_front_left_wheel_link"/>
    <child link="front_left_roller5_link"/>
    <axis xyz="0. 0. 1."/>
  </joint>
  <joint name="front_left_roller6_joint" type="continuous">
    <origin xyz="-0.0926647 -0. 0.0535 " rpy="-0.5359965 0.7778994 0.3978639"/>
    <parent link="summit_xl_front_left_wheel_link"/>
    <child link="front_left_roller6_link"/>
    <axis xyz="0. 0. 1."/>
  </joint>
  <joint name="front_left_roller7_joint" type="continuous">
    <origin xyz="-0.107 -0. 0. " rpy="-0.7853984 0. 0. "/>
    <parent link="summit_xl_front_left_wheel_link"/>
    <child link="front_left_roller7_link"/>
    <axis xyz="0. 0. 1."/>
  </joint>
  <joint name="front_left_roller8_joint" type="continuous">
    <origin xyz="-0.0926647 -0. -0.0535 " rpy="-0.5359965 -0.7778994 -0.3978639"/>
    <parent link="summit_xl_front_left_wheel_link"/>
    <child link="front_left_roller8_link"/>
    <axis xyz="0. 0. 1."/>
  </joint>
  <joint name="front_left_roller9_joint" type="continuous">
    <origin xyz="-0.0535 -0. -0.0926647" rpy="-0.0439603 -1.2045692 -0.8038372"/>
    <parent link="summit_xl_front_left_wheel_link"/>
    <child link="front_left_roller9_link"/>
    <axis xyz="0. 0. 1."/>
  </joint>
  <joint name="front_right_roller10_joint" type="continuous">
    <origin xyz="-0. 0. -0.107" rpy="0.7853982 -1.5707963 0. "/>
    <parent link="summit_xl_front_right_wheel_link"/>
    <child link="front_right_roller10_link"/>
    <axis xyz="0. 0. 1."/>
  </joint>
  <joint name="front_right_roller11_joint" type="continuous">
    <origin xyz="0.0535 0. -0.0926647" rpy="-0.0597851 1.1990727 0.8046284"/>
    <parent link="summit_xl_front_right_wheel_link"/>
    <child link="front_right_roller11_link"/>
    <axis xyz="0. 0. 1."/>
  </joint>
  <joint name="front_right_roller12_joint" type="continuous">
    <origin xyz="0.0926647 0. -0.0535 " rpy="-0.5359965 0.7778994 0.3978639"/>
    <parent link="summit_xl_front_right_wheel_link"/>
    <child link="front_right_roller12_link"/>
    <axis xyz="0. 0. 1."/>
  </joint>
  <joint name="front_right_roller1_joint" type="continuous">
    <origin xyz="0.107 0. 0. " rpy="-0.7853984 0. 0. "/>
    <parent link="summit_xl_front_right_wheel_link"/>
    <child link="front_right_roller1_link"/>
    <axis xyz="0. 0. 1."/>
  </joint>
  <joint name="front_right_roller2_joint" type="continuous">
    <origin xyz="0.0926647 0. 0.0535 " rpy="-0.5359965 -0.7778994 -0.3978639"/>
    <parent link="summit_xl_front_right_wheel_link"/>
    <child link="front_right_roller2_link"/>
    <axis xyz="0. 0. 1."/>
  </joint>
  <joint name="front_right_roller3_joint" type="continuous">
    <origin xyz="0.0535 0. 0.0926647" rpy="-0.0439603 -1.2045692 -0.8038372"/>
    <parent link="summit_xl_front_right_wheel_link"/>
    <child link="front_right_roller3_link"/>
    <axis xyz="0. 0. 1."/>
  </joint>
  <joint name="front_right_roller4_joint" type="continuous">
    <origin xyz="-0. 0. 0.107" rpy="-0.7853982 -1.5707963 0. "/>
    <parent link="summit_xl_front_right_wheel_link"/>
    <child link="front_right_roller4_link"/>
    <axis xyz="0. 0. 1."/>
  </joint>
  <joint name="front_right_roller5_joint" type="continuous">
    <origin xyz="-0.0535 0. 0.0926647" rpy="0.0439603 1.2045692 -0.8038372"/>
    <parent link="summit_xl_front_right_wheel_link"/>
    <child link="front_right_roller5_link"/>
    <axis xyz="0. 0. 1."/>
  </joint>
  <joint name="front_right_roller6_joint" type="continuous">
    <origin xyz="-0.0926647 0. 0.0535 " rpy="0.5359965 0.7778994 -0.3978639"/>
    <parent link="summit_xl_front_right_wheel_link"/>
    <child link="front_right_roller6_link"/>
    <axis xyz="0. 0. 1."/>
  </joint>
  <joint name="front_right_roller7_joint" type="continuous">
    <origin xyz="-0.107 0. 0. " rpy="0.7853984 0. 0. "/>
    <parent link="summit_xl_front_right_wheel_link"/>
    <child link="front_right_roller7_link"/>
    <axis xyz="0. 0. 1."/>
  </joint>
  <joint name="front_right_roller8_joint" type="continuous">
    <origin xyz="-0.0926647 0. -0.0535 " rpy="0.5359965 -0.7778994 0.3978639"/>
    <parent link="summit_xl_front_right_wheel_link"/>
    <child link="front_right_roller8_link"/>
    <axis xyz="0. 0. 1."/>
  </joint>
  <joint name="front_right_roller9_joint" type="continuous">
    <origin xyz="-0.0535 0. -0.0926647" rpy="0.0439603 -1.2045692 0.8038372"/>
    <parent link="summit_xl_front_right_wheel_link"/>
    <child link="front_right_roller9_link"/>
    <axis xyz="0. 0. 1."/>
  </joint>
  <joint name="joint_franka_panda_hand-Hand_Camera" type="fixed">
    <origin xyz="0.05 0. 0.0499999" rpy="-3.1415927 0. 1.5707964"/>
    <parent link="franka_panda_hand"/>
    <child link="Hand_Camera"/>
  </joint>
  <joint name="joint_rbkairos_os1_mesh-OS1" type="fixed">
    <origin xyz="0. 0. 0." rpy="0. 0. 0."/>
    <parent link="rbkairos_os1_mesh"/>
    <child link="OS1"/>
  </joint>
  <joint name="joint_robot_front_rgbd_camera_link-Main_Camera" type="fixed">
    <origin xyz="0.015 -0.0175 0. " rpy="1.5707964 0. -1.5707964"/>
    <parent link="robot_front_rgbd_camera_link"/>
    <child link="Main_Camera"/>
  </joint>
  <joint name="os1_joint" type="fixed">
    <origin xyz="0.0000034 0. 0.4133 " rpy="0. 0. 0.0031644"/>
    <parent link="robot_front_left_pole_sup_link"/>
    <child link="rbkairos_os1_mesh"/>
  </joint>
  <joint name="panda_finger_joint1" type="prismatic">
    <origin xyz="0. 0. 0.0584" rpy="0. 0. 1.5707964"/>
    <parent link="franka_panda_hand"/>
    <child link="panda_leftfinger"/>
    <axis xyz="1. 0. 0."/>
    <limit lower="0." upper="0.04" effort="720." velocity="10."/>
  </joint>
  <joint name="panda_finger_joint2" type="prismatic">
    <origin xyz="0. 0. 0.0584" rpy="0. 0. -1.5707963"/>
    <parent link="franka_panda_hand"/>
    <child link="panda_rightfinger"/>
    <axis xyz="1. 0. 0."/>
    <limit lower="0." upper="0.04" effort="720." velocity="10."/>
  </joint>
  <joint name="panda_hand_joint" type="fixed">
    <origin xyz="0. 0. 0." rpy="1.5707964 -0.7853981 -1.5707964"/>
    <parent link="panda_link8"/>
    <child link="franka_panda_hand"/>
  </joint>
  <joint name="panda_joint1" type="revolute">
    <origin xyz="-0. -0. 0.3329999" rpy="0. -1.5707961 0.0015925"/>
    <parent link="panda_link0"/>
    <child link="panda_link1"/>
    <axis xyz="1. 0. 0."/>
    <limit lower="-2.8973001" upper="2.8973001" effort="5220." velocity="10.0000005"/>
  </joint>
  <joint name="panda_joint2" type="revolute">
    <origin xyz="-0. -0. -0." rpy="-0.0000002 0. 1.5707964"/>
    <parent link="panda_link1"/>
    <child link="panda_link2"/>
    <axis xyz="1. 0. 0."/>
    <limit lower="-1.7628" upper="1.7628" effort="5220." velocity="10.0000005"/>
  </joint>
  <joint name="panda_joint3" type="revolute">
    <origin xyz="0.0000001 -0.316 0. " rpy="0. -0. -1.570796"/>
    <parent link="panda_link2"/>
    <child link="panda_link3"/>
    <axis xyz="1. 0. 0."/>
    <limit lower="-2.8973001" upper="2.8973001" effort="5220." velocity="10.0000005"/>
  </joint>
  <joint name="panda_joint4" type="revolute">
    <origin xyz="0. 0. -0.0825" rpy="0. 0. -1.5707964"/>
    <parent link="panda_link3"/>
    <child link="panda_link4"/>
    <axis xyz="1. 0. 0."/>
    <limit lower="-3.0718" upper="-0.0698" effort="5220." velocity="10.0000005"/>
  </joint>
  <joint name="panda_joint5" type="revolute">
    <origin xyz="0. 0.3839999 0.0824999" rpy="0. 0. 1.5707964"/>
    <parent link="panda_link4"/>
    <child link="panda_link5"/>
    <axis xyz="1. 0. 0."/>
    <limit lower="-2.8973001" upper="2.8973001" effort="720." velocity="10.0000005"/>
  </joint>
  <joint name="panda_joint6" type="revolute">
    <origin xyz="0. 0. 0." rpy="0. 0. -1.5707964"/>
    <parent link="panda_link5"/>
    <child link="panda_link6"/>
    <axis xyz="1. 0. 0."/>
    <limit lower="-0.0175" upper="3.7525" effort="720." velocity="10.0000005"/>
  </joint>
  <joint name="panda_joint7" type="revolute">
    <origin xyz="0. -0. -0.0879999" rpy="0. 0. -1.5707964"/>
    <parent link="panda_link6"/>
    <child link="panda_link7"/>
    <axis xyz="1. 0. 0."/>
    <limit lower="-2.8973001" upper="2.8973001" effort="720." velocity="10.0000005"/>
  </joint>
  <joint name="panda_joint8" type="fixed">
    <origin xyz="0.1069998 0. -0.0000001" rpy="3.1415925 0. -3.1415923"/>
    <parent link="panda_link7"/>
    <child link="panda_link8"/>
  </joint>
  <joint name="robot_arm_joint" type="fixed">
    <origin xyz="-0.273 0. 0.56212" rpy="0. 0. 3.14"/>
    <parent link="base_link"/>
    <child link="panda_link0"/>
  </joint>
  <joint name="robot_back_left_wheel_joint" type="continuous">
    <origin xyz="-0.21528 0.269 -0. " rpy="0. 0. 0."/>
    <parent link="base_link"/>
    <child link="summit_xl_back_left_wheel_link"/>
    <axis xyz="0. 1. 0."/>
  </joint>
  <joint name="robot_back_right_wheel_joint" type="continuous">
    <origin xyz="-0.21528 -0.269 -0. " rpy="0. 0. 0."/>
    <parent link="base_link"/>
    <child link="summit_xl_back_right_wheel_link"/>
    <axis xyz="0. 1. 0."/>
  </joint>
  <joint name="robot_base_docking_joint" type="fixed">
    <origin xyz="0.35 0. 0.09" rpy="0. 0. 0."/>
    <parent link="base_link"/>
    <child link="robot_base_docking_contact"/>
  </joint>
  <joint name="robot_base_footprint_joint" type="fixed">
    <origin xyz="0.0103077 -0.0236575 0.1250255" rpy="0.0003379 -0.0016197 0.011564 "/>
    <parent link="base_footprint"/>
    <child link="base_link"/>
  </joint>
  <joint name="robot_base_logo_front_joint" type="fixed">
    <origin xyz="0.345 0. 0. " rpy="0. 0. -1.5707964"/>
    <parent link="base_link"/>
    <child link="robot_base_logo_front"/>
  </joint>
  <joint name="robot_base_logo_left_joint" type="fixed">
    <origin xyz="0. 0.2894 0.35562" rpy="0. 0. 0."/>
    <parent link="base_link"/>
    <child link="robot_base_logo_left"/>
  </joint>
  <joint name="robot_base_logo_rear_joint" type="fixed">
    <origin xyz="-0.345 0. 0. " rpy="0. 0. 1.5707964"/>
    <parent link="base_link"/>
    <child link="robot_base_logo_rear"/>
  </joint>
  <joint name="robot_base_logo_right_joint" type="fixed">
    <origin xyz="0. -0.28931 0.35562" rpy="0. 0. -3.1415925"/>
    <parent link="base_link"/>
    <child link="robot_base_logo_right"/>
  </joint>
  <joint name="robot_base_tapa_joint" type="fixed">
    <origin xyz="0. 0. 0.56162" rpy="0. 0. 0."/>
    <parent link="base_link"/>
    <child link="robot_base_chapa"/>
  </joint>
  <joint name="robot_front_laser_base_joint" type="fixed">
    <origin xyz="0.42101 -0.32716 0.16687" rpy="-3.1415927 0.0000001 -0.7853982"/>
    <parent link="base_link"/>
    <child link="robot_front_laser_base_link"/>
  </joint>
  <joint name="robot_front_laser_body_joint" type="fixed">
    <origin xyz="0.051 0. 0. " rpy="0. 0. 0."/>
    <parent link="robot_front_laser_base_link"/>
    <child link="robot_front_laser_body_link"/>
  </joint>
  <joint name="robot_front_laser_scan_joint" type="fixed">
    <origin xyz="0. -0.0015 0.1237" rpy="-3.1415925 0. 0. "/>
    <parent link="robot_front_laser_body_link"/>
    <child link="robot_front_laser_link"/>
  </joint>
  <joint name="robot_front_left_pole_joint" type="fixed">
    <origin xyz="0.31775 0.2933 0.42762" rpy="0. 0. 3.14"/>
    <parent link="base_link"/>
    <child link="robot_front_left_pole_link"/>
  </joint>
  <joint name="robot_front_left_pole_sup_joint" type="fixed">
    <origin xyz="0. -0.023 0. " rpy="0. 0. 3.14"/>
    <parent link="robot_front_left_pole_link"/>
    <child link="robot_front_left_pole_sup_link"/>
  </joint>
  <joint name="robot_front_left_rgb_camera_1_joint" type="fixed">
    <origin xyz="0. 0.027 0.315" rpy="0. 0. 0."/>
    <parent link="robot_front_left_pole_sup_link"/>
    <child link="robot_front_left_rgb_camera_1_link"/>
  </joint>
  <joint name="robot_front_left_rgb_camera_1_optical_joint" type="fixed">
    <origin xyz="0.07 0. 0. " rpy="0. 0. 0."/>
    <parent link="robot_front_left_rgb_camera_1_link"/>
    <child link="robot_front_left_rgb_camera_1_optical_frame"/>
  </joint>
  <joint name="robot_front_left_rgb_camera_2_joint" type="fixed">
    <origin xyz="0. -0.02706 0.315 " rpy="0. 0. 3.14"/>
    <parent link="robot_front_left_pole_sup_link"/>
    <child link="robot_front_left_rgb_camera_2_link"/>
  </joint>
  <joint name="robot_front_left_rgb_camera_2_optical_joint" type="fixed">
    <origin xyz="0.07 0. 0. " rpy="0. 0. 0."/>
    <parent link="robot_front_left_rgb_camera_2_link"/>
    <child link="robot_front_left_rgb_camera_2_optical_frame"/>
  </joint>
  <joint name="robot_front_left_wheel_joint" type="continuous">
    <origin xyz="0.21528 0.269 -0. " rpy="0. 0. 0."/>
    <parent link="base_link"/>
    <child link="summit_xl_front_left_wheel_link"/>
    <axis xyz="0. 1. 0."/>
  </joint>
  <joint name="robot_front_rgbd_camera_base_joint" type="fixed">
    <origin xyz="0.3585 0. 0.25062" rpy="0. 0. 0."/>
    <parent link="base_link"/>
    <child link="robot_front_rgbd_camera_base_link"/>
  </joint>
  <joint name="robot_front_rgbd_camera_color_joint" type="fixed">
    <origin xyz="0. 0.015 0. " rpy="0. 0. 0."/>
    <parent link="robot_front_rgbd_camera_link"/>
    <child link="robot_front_rgbd_camera_color_frame"/>
  </joint>
  <joint name="robot_front_rgbd_camera_color_optical_joint" type="fixed">
    <origin xyz="0. 0. 0." rpy="-1.5707964 0. -1.5707964"/>
    <parent link="robot_front_rgbd_camera_color_frame"/>
    <child link="robot_front_rgbd_camera_color_optical_frame"/>
  </joint>
  <joint name="robot_front_rgbd_camera_depth_joint" type="fixed">
    <origin xyz="0. 0. 0." rpy="0. 0. 0."/>
    <parent link="robot_front_rgbd_camera_link"/>
    <child link="robot_front_rgbd_camera_depth_frame"/>
  </joint>
  <joint name="robot_front_rgbd_camera_depth_optical_joint" type="fixed">
    <origin xyz="0. 0. 0." rpy="-1.5707964 0. -1.5707964"/>
    <parent link="robot_front_rgbd_camera_depth_frame"/>
    <child link="robot_front_rgbd_camera_depth_optical_frame"/>
  </joint>
  <joint name="robot_front_rgbd_camera_infra1_joint" type="fixed">
    <origin xyz="0. 0. 0." rpy="0. 0. 0."/>
    <parent link="robot_front_rgbd_camera_link"/>
    <child link="robot_front_rgbd_camera_infra1_frame"/>
  </joint>
  <joint name="robot_front_rgbd_camera_infra1_optical_joint" type="fixed">
    <origin xyz="0. 0. 0." rpy="-1.5707964 0. -1.5707964"/>
    <parent link="robot_front_rgbd_camera_infra1_frame"/>
    <child link="robot_front_rgbd_camera_infra1_optical_frame"/>
  </joint>
  <joint name="robot_front_rgbd_camera_infra2_joint" type="fixed">
    <origin xyz="0. -0.05 0. " rpy="0. 0. 0."/>
    <parent link="robot_front_rgbd_camera_link"/>
    <child link="robot_front_rgbd_camera_infra2_frame"/>
  </joint>
  <joint name="robot_front_rgbd_camera_infra2_optical_joint" type="fixed">
    <origin xyz="0. 0. 0." rpy="-1.5707964 0. -1.5707964"/>
    <parent link="robot_front_rgbd_camera_infra2_frame"/>
    <child link="robot_front_rgbd_camera_infra2_optical_frame"/>
  </joint>
  <joint name="robot_front_rgbd_camera_joint" type="fixed">
    <origin xyz="0.01 0.02 0. " rpy="0. 0. 0."/>
    <parent link="robot_front_rgbd_camera_base_link"/>
    <child link="robot_front_rgbd_camera_link"/>
  </joint>
  <joint name="robot_front_right_pole_joint" type="fixed">
    <origin xyz="0.31775 -0.2933 0.42762" rpy="0. 0. 0."/>
    <parent link="base_link"/>
    <child link="robot_front_right_pole_link"/>
  </joint>
  <joint name="robot_front_right_pole_sup_joint" type="fixed">
    <origin xyz="0. -0.023 0. " rpy="0. 0. 3.14"/>
    <parent link="robot_front_right_pole_link"/>
    <child link="robot_front_right_pole_sup_link"/>
  </joint>
  <joint name="robot_front_right_wheel_joint" type="continuous">
    <origin xyz="0.21528 -0.269 -0. " rpy="0. 0. 0."/>
    <parent link="base_link"/>
    <child link="summit_xl_front_right_wheel_link"/>
    <axis xyz="0. 1. 0."/>
  </joint>
  <joint name="robot_imu_joint" type="fixed">
    <origin xyz="0.127 -0.129 0.212" rpy="0. 0. 0."/>
    <parent link="base_link"/>
    <child link="robot_imu_link"/>
  </joint>
  <joint name="robot_pantilt_base_joint" type="fixed">
    <origin xyz="0. 0. 0.3833" rpy="0. 0. 3.14159"/>
    <parent link="robot_front_right_pole_sup_link"/>
    <child link="robot_pantilt_base_link"/>
  </joint>
  <joint name="robot_pantilt_pan_joint" type="revolute">
    <origin xyz="0. 0. 0." rpy="0. 0. 0."/>
    <parent link="robot_pantilt_base_link"/>
    <child link="robot_pantilt_pan_link"/>
    <axis xyz="0. 0. 1."/>
    <limit lower="-3.1415927" upper="3.1415927" effort="100." velocity="50.0000015"/>
  </joint>
  <joint name="robot_pantilt_tilt_joint" type="revolute">
    <origin xyz="0. 0. 0.08305" rpy="0. 0. 0."/>
    <parent link="robot_pantilt_pan_link"/>
    <child link="robot_pantilt_tilt_link"/>
    <axis xyz="0. 1. 0."/>
    <limit lower="-1.0471976" upper="1.0471976" effort="100." velocity="5.0000003"/>
  </joint>
  <joint name="robot_rear_laser_base_joint" type="fixed">
    <origin xyz="-0.42101 0.32716 0.16687" rpy="-3.1415927 0.0000001 2.3561945"/>
    <parent link="base_link"/>
    <child link="robot_rear_laser_base_link"/>
  </joint>
  <joint name="robot_rear_laser_body_joint" type="fixed">
    <origin xyz="0.051 0. 0. " rpy="0. 0. 0."/>
    <parent link="robot_rear_laser_base_link"/>
    <child link="robot_rear_laser_body_link"/>
  </joint>
  <joint name="robot_rear_laser_scan_joint" type="fixed">
    <origin xyz="0. -0.0015 0.1237" rpy="-3.1415925 0. 0. "/>
    <parent link="robot_rear_laser_body_link"/>
    <child link="robot_rear_laser_link"/>
  </joint>
  <joint name="robot_top_right_rgbd_camera_1_camera_base_to_body" type="fixed">
    <origin xyz="-0.0757 0. 0.008 " rpy="0. 0. 0."/>
    <parent link="robot_top_right_rgbd_camera_1_link"/>
    <child link="robot_top_right_rgbd_camera_1_camera_body"/>
  </joint>
  <joint name="robot_top_right_rgbd_camera_1_camera_base_to_visor" type="fixed">
    <origin xyz="0. 0. 0." rpy="0. 0. 0."/>
    <parent link="robot_top_right_rgbd_camera_1_link"/>
    <child link="robot_top_right_rgbd_camera_1_camera_visor"/>
  </joint>
  <joint name="robot_top_right_rgbd_camera_1_joint" type="fixed">
    <origin xyz="-0.069 0.085 0.264" rpy="0. 0. 1.57"/>
    <parent link="robot_front_right_pole_sup_link"/>
    <child link="robot_top_right_rgbd_camera_1_link"/>
  </joint>
  <joint name="robot_top_right_rgbd_camera_2_camera_base_to_body" type="fixed">
    <origin xyz="-0.0757 0. 0.008 " rpy="0. 0. 0."/>
    <parent link="robot_top_right_rgbd_camera_2_link"/>
    <child link="robot_top_right_rgbd_camera_2_camera_body"/>
  </joint>
  <joint name="robot_top_right_rgbd_camera_2_camera_base_to_visor" type="fixed">
    <origin xyz="0. 0. 0." rpy="0. 0. 0."/>
    <parent link="robot_top_right_rgbd_camera_2_link"/>
    <child link="robot_top_right_rgbd_camera_2_camera_visor"/>
  </joint>
  <joint name="robot_top_right_rgbd_camera_2_joint" type="fixed">
    <origin xyz="0.0775 0. 0.0475" rpy="0. 0. 0."/>
    <parent link="robot_pantilt_tilt_link"/>
    <child link="robot_top_right_rgbd_camera_2_link"/>
  </joint>
  <link name="Hand_Camera"/>
  <link name="Main_Camera"/>
  <link name="OS1"/>
  <link name="back_left_roller10_link">
    <inertial>
      <origin xyz="0. 0. 0." rpy="0. 0. 0."/>
      <mass value="0.0141372"/>
      <inertia ixx="0." ixy="0." ixz="0." iyy="0." iyz="0." izz="0."/>
    </inertial>
    <visual>
      <origin xyz="-0.00051 0. -0.035 " rpy="0. 0. 0."/>
      <geometry>
        <sphere radius="0.015"/>
      </geometry>
    </visual>
    <visual>
      <origin xyz="-0.00051 0. 0.035 " rpy="0. 0. 0."/>
      <geometry>
        <sphere radius="0.015"/>
      </geometry>
    </visual>
    <visual>
      <origin xyz="0. 0. 0." rpy="0. 0. 0."/>
      <geometry>
        <sphere radius="0.019"/>
      </geometry>
    </visual>
    <visual>
      <origin xyz="0. 0. 0.0175" rpy="0. 0. 0."/>
      <geometry>
        <sphere radius="0.017"/>
      </geometry>
    </visual>
    <visual>
      <origin xyz="0. 0. -0.0175" rpy="0. 0. 0."/>
      <geometry>
        <sphere radius="0.017"/>
      </geometry>
    </visual>
    <collision>
      <origin xyz="-0.00051 0. -0.035 " rpy="0. 0. 0."/>
      <geometry>
        <sphere radius="0.015"/>
      </geometry>
    </collision>
    <collision>
      <origin xyz="-0.00051 0. 0.035 " rpy="0. 0. 0."/>
      <geometry>
        <sphere radius="0.015"/>
      </geometry>
    </collision>
    <collision>
      <origin xyz="0. 0. 0." rpy="0. 0. 0."/>
      <geometry>
        <sphere radius="0.019"/>
      </geometry>
    </collision>
    <collision>
      <origin xyz="0. 0. 0.0175" rpy="0. 0. 0."/>
      <geometry>
        <sphere radius="0.017"/>
      </geometry>
    </collision>
    <collision>
      <origin xyz="0. 0. -0.0175" rpy="0. 0. 0."/>
      <geometry>
        <sphere radius="0.017"/>
      </geometry>
    </collision>
  </link>
  <link name="back_left_roller11_link">
    <inertial>
      <origin xyz="0. 0. 0." rpy="0. 0. 0."/>
      <mass value="0.0141372"/>
      <inertia ixx="0." ixy="0." ixz="0." iyy="0." iyz="0." izz="0."/>
    </inertial>
    <visual>
      <origin xyz="-0.00051 0. -0.035 " rpy="0. 0. 0."/>
      <geometry>
        <sphere radius="0.015"/>
      </geometry>
    </visual>
    <visual>
      <origin xyz="-0.00051 0. 0.035 " rpy="0. 0. 0."/>
      <geometry>
        <sphere radius="0.015"/>
      </geometry>
    </visual>
    <visual>
      <origin xyz="0. 0. 0." rpy="0. 0. 0."/>
      <geometry>
        <sphere radius="0.019"/>
      </geometry>
    </visual>
    <visual>
      <origin xyz="0. 0. 0.0175" rpy="0. 0. 0."/>
      <geometry>
        <sphere radius="0.017"/>
      </geometry>
    </visual>
    <visual>
      <origin xyz="0. 0. -0.0175" rpy="0. 0. 0."/>
      <geometry>
        <sphere radius="0.017"/>
      </geometry>
    </visual>
    <collision>
      <origin xyz="-0.00051 0. -0.035 " rpy="0. 0. 0."/>
      <geometry>
        <sphere radius="0.015"/>
      </geometry>
    </collision>
    <collision>
      <origin xyz="-0.00051 0. 0.035 " rpy="0. 0. 0."/>
      <geometry>
        <sphere radius="0.015"/>
      </geometry>
    </collision>
    <collision>
      <origin xyz="0. 0. 0." rpy="0. 0. 0."/>
      <geometry>
        <sphere radius="0.019"/>
      </geometry>
    </collision>
    <collision>
      <origin xyz="0. 0. 0.0175" rpy="0. 0. 0."/>
      <geometry>
        <sphere radius="0.017"/>
      </geometry>
    </collision>
    <collision>
      <origin xyz="0. 0. -0.0175" rpy="0. 0. 0."/>
      <geometry>
        <sphere radius="0.017"/>
      </geometry>
    </collision>
  </link>
  <link name="back_left_roller12_link">
    <inertial>
      <origin xyz="0. 0. 0." rpy="0. 0. 0."/>
      <mass value="0.0141372"/>
      <inertia ixx="0." ixy="0." ixz="0." iyy="0." iyz="0." izz="0."/>
    </inertial>
    <visual>
      <origin xyz="-0.00051 0. -0.035 " rpy="0. 0. 0."/>
      <geometry>
        <sphere radius="0.015"/>
      </geometry>
    </visual>
    <visual>
      <origin xyz="-0.00051 0. 0.035 " rpy="0. 0. 0."/>
      <geometry>
        <sphere radius="0.015"/>
      </geometry>
    </visual>
    <visual>
      <origin xyz="0. 0. 0." rpy="0. 0. 0."/>
      <geometry>
        <sphere radius="0.019"/>
      </geometry>
    </visual>
    <visual>
      <origin xyz="0. 0. 0.0175" rpy="0. 0. 0."/>
      <geometry>
        <sphere radius="0.017"/>
      </geometry>
    </visual>
    <visual>
      <origin xyz="0. 0. -0.0175" rpy="0. 0. 0."/>
      <geometry>
        <sphere radius="0.017"/>
      </geometry>
    </visual>
    <collision>
      <origin xyz="-0.00051 0. -0.035 " rpy="0. 0. 0."/>
      <geometry>
        <sphere radius="0.015"/>
      </geometry>
    </collision>
    <collision>
      <origin xyz="-0.00051 0. 0.035 " rpy="0. 0. 0."/>
      <geometry>
        <sphere radius="0.015"/>
      </geometry>
    </collision>
    <collision>
      <origin xyz="0. 0. 0." rpy="0. 0. 0."/>
      <geometry>
        <sphere radius="0.019"/>
      </geometry>
    </collision>
    <collision>
      <origin xyz="0. 0. 0.0175" rpy="0. 0. 0."/>
      <geometry>
        <sphere radius="0.017"/>
      </geometry>
    </collision>
    <collision>
      <origin xyz="0. 0. -0.0175" rpy="0. 0. 0."/>
      <geometry>
        <sphere radius="0.017"/>
      </geometry>
    </collision>
  </link>
  <link name="back_left_roller1_link">
    <inertial>
      <origin xyz="0. 0. 0." rpy="0. 0. 0."/>
      <mass value="0.0141372"/>
      <inertia ixx="0." ixy="0." ixz="0." iyy="0." iyz="0." izz="0."/>
    </inertial>
    <visual>
      <origin xyz="-0.00051 0. -0.035 " rpy="0. 0. 0."/>
      <geometry>
        <sphere radius="0.015"/>
      </geometry>
    </visual>
    <visual>
      <origin xyz="-0.00051 0. 0.035 " rpy="0. 0. 0."/>
      <geometry>
        <sphere radius="0.015"/>
      </geometry>
    </visual>
    <visual>
      <origin xyz="0. 0. 0." rpy="0. 0. 0."/>
      <geometry>
        <sphere radius="0.019"/>
      </geometry>
    </visual>
    <visual>
      <origin xyz="0. 0. 0.0175" rpy="0. 0. 0."/>
      <geometry>
        <sphere radius="0.017"/>
      </geometry>
    </visual>
    <visual>
      <origin xyz="0. 0. -0.0175" rpy="0. 0. 0."/>
      <geometry>
        <sphere radius="0.017"/>
      </geometry>
    </visual>
    <collision>
      <origin xyz="-0.00051 0. -0.035 " rpy="0. 0. 0."/>
      <geometry>
        <sphere radius="0.015"/>
      </geometry>
    </collision>
    <collision>
      <origin xyz="-0.00051 0. 0.035 " rpy="0. 0. 0."/>
      <geometry>
        <sphere radius="0.015"/>
      </geometry>
    </collision>
    <collision>
      <origin xyz="0. 0. 0." rpy="0. 0. 0."/>
      <geometry>
        <sphere radius="0.019"/>
      </geometry>
    </collision>
    <collision>
      <origin xyz="0. 0. 0.0175" rpy="0. 0. 0."/>
      <geometry>
        <sphere radius="0.017"/>
      </geometry>
    </collision>
    <collision>
      <origin xyz="0. 0. -0.0175" rpy="0. 0. 0."/>
      <geometry>
        <sphere radius="0.017"/>
      </geometry>
    </collision>
  </link>
  <link name="back_left_roller2_link">
    <inertial>
      <origin xyz="0. 0. 0." rpy="0. 0. 0."/>
      <mass value="0.0141372"/>
      <inertia ixx="0." ixy="0." ixz="0." iyy="0." iyz="0." izz="0."/>
    </inertial>
    <visual>
      <origin xyz="-0.00051 0. -0.035 " rpy="0. 0. 0."/>
      <geometry>
        <sphere radius="0.015"/>
      </geometry>
    </visual>
    <visual>
      <origin xyz="-0.00051 0. 0.035 " rpy="0. 0. 0."/>
      <geometry>
        <sphere radius="0.015"/>
      </geometry>
    </visual>
    <visual>
      <origin xyz="0. 0. 0." rpy="0. 0. 0."/>
      <geometry>
        <sphere radius="0.019"/>
      </geometry>
    </visual>
    <visual>
      <origin xyz="0. 0. 0.0175" rpy="0. 0. 0."/>
      <geometry>
        <sphere radius="0.017"/>
      </geometry>
    </visual>
    <visual>
      <origin xyz="0. 0. -0.0175" rpy="0. 0. 0."/>
      <geometry>
        <sphere radius="0.017"/>
      </geometry>
    </visual>
    <collision>
      <origin xyz="-0.00051 0. -0.035 " rpy="0. 0. 0."/>
      <geometry>
        <sphere radius="0.015"/>
      </geometry>
    </collision>
    <collision>
      <origin xyz="-0.00051 0. 0.035 " rpy="0. 0. 0."/>
      <geometry>
        <sphere radius="0.015"/>
      </geometry>
    </collision>
    <collision>
      <origin xyz="0. 0. 0." rpy="0. 0. 0."/>
      <geometry>
        <sphere radius="0.019"/>
      </geometry>
    </collision>
    <collision>
      <origin xyz="0. 0. 0.0175" rpy="0. 0. 0."/>
      <geometry>
        <sphere radius="0.017"/>
      </geometry>
    </collision>
    <collision>
      <origin xyz="0. 0. -0.0175" rpy="0. 0. 0."/>
      <geometry>
        <sphere radius="0.017"/>
      </geometry>
    </collision>
  </link>
  <link name="back_left_roller3_link">
    <inertial>
      <origin xyz="0. 0. 0." rpy="0. 0. 0."/>
      <mass value="0.0141372"/>
      <inertia ixx="0." ixy="0." ixz="0." iyy="0." iyz="0." izz="0."/>
    </inertial>
    <visual>
      <origin xyz="-0.00051 0. -0.035 " rpy="0. 0. 0."/>
      <geometry>
        <sphere radius="0.015"/>
      </geometry>
    </visual>
    <visual>
      <origin xyz="-0.00051 0. 0.035 " rpy="0. 0. 0."/>
      <geometry>
        <sphere radius="0.015"/>
      </geometry>
    </visual>
    <visual>
      <origin xyz="0. 0. 0." rpy="0. 0. 0."/>
      <geometry>
        <sphere radius="0.019"/>
      </geometry>
    </visual>
    <visual>
      <origin xyz="0. 0. 0.0175" rpy="0. 0. 0."/>
      <geometry>
        <sphere radius="0.017"/>
      </geometry>
    </visual>
    <visual>
      <origin xyz="0. 0. -0.0175" rpy="0. 0. 0."/>
      <geometry>
        <sphere radius="0.017"/>
      </geometry>
    </visual>
    <collision>
      <origin xyz="-0.00051 0. -0.035 " rpy="0. 0. 0."/>
      <geometry>
        <sphere radius="0.015"/>
      </geometry>
    </collision>
    <collision>
      <origin xyz="-0.00051 0. 0.035 " rpy="0. 0. 0."/>
      <geometry>
        <sphere radius="0.015"/>
      </geometry>
    </collision>
    <collision>
      <origin xyz="0. 0. 0." rpy="0. 0. 0."/>
      <geometry>
        <sphere radius="0.019"/>
      </geometry>
    </collision>
    <collision>
      <origin xyz="0. 0. 0.0175" rpy="0. 0. 0."/>
      <geometry>
        <sphere radius="0.017"/>
      </geometry>
    </collision>
    <collision>
      <origin xyz="0. 0. -0.0175" rpy="0. 0. 0."/>
      <geometry>
        <sphere radius="0.017"/>
      </geometry>
    </collision>
  </link>
  <link name="back_left_roller4_link">
    <inertial>
      <origin xyz="0. 0. 0." rpy="0. 0. 0."/>
      <mass value="0.0141372"/>
      <inertia ixx="0." ixy="0." ixz="0." iyy="0." iyz="0." izz="0."/>
    </inertial>
    <visual>
      <origin xyz="-0.00051 0. -0.035 " rpy="0. 0. 0."/>
      <geometry>
        <sphere radius="0.015"/>
      </geometry>
    </visual>
    <visual>
      <origin xyz="-0.00051 0. 0.035 " rpy="0. 0. 0."/>
      <geometry>
        <sphere radius="0.015"/>
      </geometry>
    </visual>
    <visual>
      <origin xyz="0. 0. 0." rpy="0. 0. 0."/>
      <geometry>
        <sphere radius="0.019"/>
      </geometry>
    </visual>
    <visual>
      <origin xyz="0. 0. 0.0175" rpy="0. 0. 0."/>
      <geometry>
        <sphere radius="0.017"/>
      </geometry>
    </visual>
    <visual>
      <origin xyz="0. 0. -0.0175" rpy="0. 0. 0."/>
      <geometry>
        <sphere radius="0.017"/>
      </geometry>
    </visual>
    <collision>
      <origin xyz="-0.00051 0. -0.035 " rpy="0. 0. 0."/>
      <geometry>
        <sphere radius="0.015"/>
      </geometry>
    </collision>
    <collision>
      <origin xyz="-0.00051 0. 0.035 " rpy="0. 0. 0."/>
      <geometry>
        <sphere radius="0.015"/>
      </geometry>
    </collision>
    <collision>
      <origin xyz="0. 0. 0." rpy="0. 0. 0."/>
      <geometry>
        <sphere radius="0.019"/>
      </geometry>
    </collision>
    <collision>
      <origin xyz="0. 0. 0.0175" rpy="0. 0. 0."/>
      <geometry>
        <sphere radius="0.017"/>
      </geometry>
    </collision>
    <collision>
      <origin xyz="0. 0. -0.0175" rpy="0. 0. 0."/>
      <geometry>
        <sphere radius="0.017"/>
      </geometry>
    </collision>
  </link>
  <link name="back_left_roller5_link">
    <inertial>
      <origin xyz="0. 0. 0." rpy="0. 0. 0."/>
      <mass value="0.0141372"/>
      <inertia ixx="0." ixy="0." ixz="0." iyy="0." iyz="0." izz="0."/>
    </inertial>
    <visual>
      <origin xyz="-0.00051 0. -0.035 " rpy="0. 0. 0."/>
      <geometry>
        <sphere radius="0.015"/>
      </geometry>
    </visual>
    <visual>
      <origin xyz="-0.00051 0. 0.035 " rpy="0. 0. 0."/>
      <geometry>
        <sphere radius="0.015"/>
      </geometry>
    </visual>
    <visual>
      <origin xyz="0. 0. 0." rpy="0. 0. 0."/>
      <geometry>
        <sphere radius="0.019"/>
      </geometry>
    </visual>
    <visual>
      <origin xyz="0. 0. 0.0175" rpy="0. 0. 0."/>
      <geometry>
        <sphere radius="0.017"/>
      </geometry>
    </visual>
    <visual>
      <origin xyz="0. 0. -0.0175" rpy="0. 0. 0."/>
      <geometry>
        <sphere radius="0.017"/>
      </geometry>
    </visual>
    <collision>
      <origin xyz="-0.00051 0. -0.035 " rpy="0. 0. 0."/>
      <geometry>
        <sphere radius="0.015"/>
      </geometry>
    </collision>
    <collision>
      <origin xyz="-0.00051 0. 0.035 " rpy="0. 0. 0."/>
      <geometry>
        <sphere radius="0.015"/>
      </geometry>
    </collision>
    <collision>
      <origin xyz="0. 0. 0." rpy="0. 0. 0."/>
      <geometry>
        <sphere radius="0.019"/>
      </geometry>
    </collision>
    <collision>
      <origin xyz="0. 0. 0.0175" rpy="0. 0. 0."/>
      <geometry>
        <sphere radius="0.017"/>
      </geometry>
    </collision>
    <collision>
      <origin xyz="0. 0. -0.0175" rpy="0. 0. 0."/>
      <geometry>
        <sphere radius="0.017"/>
      </geometry>
    </collision>
  </link>
  <link name="back_left_roller6_link">
    <inertial>
      <origin xyz="0. 0. 0." rpy="0. 0. 0."/>
      <mass value="0.0141372"/>
      <inertia ixx="0." ixy="0." ixz="0." iyy="0." iyz="0." izz="0."/>
    </inertial>
    <visual>
      <origin xyz="-0.00051 0. -0.035 " rpy="0. 0. 0."/>
      <geometry>
        <sphere radius="0.015"/>
      </geometry>
    </visual>
    <visual>
      <origin xyz="-0.00051 0. 0.035 " rpy="0. 0. 0."/>
      <geometry>
        <sphere radius="0.015"/>
      </geometry>
    </visual>
    <visual>
      <origin xyz="0. 0. 0." rpy="0. 0. 0."/>
      <geometry>
        <sphere radius="0.019"/>
      </geometry>
    </visual>
    <visual>
      <origin xyz="0. 0. 0.0175" rpy="0. 0. 0."/>
      <geometry>
        <sphere radius="0.017"/>
      </geometry>
    </visual>
    <visual>
      <origin xyz="0. 0. -0.0175" rpy="0. 0. 0."/>
      <geometry>
        <sphere radius="0.017"/>
      </geometry>
    </visual>
    <collision>
      <origin xyz="-0.00051 0. -0.035 " rpy="0. 0. 0."/>
      <geometry>
        <sphere radius="0.015"/>
      </geometry>
    </collision>
    <collision>
      <origin xyz="-0.00051 0. 0.035 " rpy="0. 0. 0."/>
      <geometry>
        <sphere radius="0.015"/>
      </geometry>
    </collision>
    <collision>
      <origin xyz="0. 0. 0." rpy="0. 0. 0."/>
      <geometry>
        <sphere radius="0.019"/>
      </geometry>
    </collision>
    <collision>
      <origin xyz="0. 0. 0.0175" rpy="0. 0. 0."/>
      <geometry>
        <sphere radius="0.017"/>
      </geometry>
    </collision>
    <collision>
      <origin xyz="0. 0. -0.0175" rpy="0. 0. 0."/>
      <geometry>
        <sphere radius="0.017"/>
      </geometry>
    </collision>
  </link>
  <link name="back_left_roller7_link">
    <inertial>
      <origin xyz="0. 0. 0." rpy="0. 0. 0."/>
      <mass value="0.0141372"/>
      <inertia ixx="0." ixy="0." ixz="0." iyy="0." iyz="0." izz="0."/>
    </inertial>
    <visual>
      <origin xyz="-0.00051 0. -0.035 " rpy="0. 0. 0."/>
      <geometry>
        <sphere radius="0.015"/>
      </geometry>
    </visual>
    <visual>
      <origin xyz="-0.00051 0. 0.035 " rpy="0. 0. 0."/>
      <geometry>
        <sphere radius="0.015"/>
      </geometry>
    </visual>
    <visual>
      <origin xyz="0. 0. 0." rpy="0. 0. 0."/>
      <geometry>
        <sphere radius="0.019"/>
      </geometry>
    </visual>
    <visual>
      <origin xyz="0. 0. 0.0175" rpy="0. 0. 0."/>
      <geometry>
        <sphere radius="0.017"/>
      </geometry>
    </visual>
    <visual>
      <origin xyz="0. 0. -0.0175" rpy="0. 0. 0."/>
      <geometry>
        <sphere radius="0.017"/>
      </geometry>
    </visual>
    <collision>
      <origin xyz="-0.00051 0. -0.035 " rpy="0. 0. 0."/>
      <geometry>
        <sphere radius="0.015"/>
      </geometry>
    </collision>
    <collision>
      <origin xyz="-0.00051 0. 0.035 " rpy="0. 0. 0."/>
      <geometry>
        <sphere radius="0.015"/>
      </geometry>
    </collision>
    <collision>
      <origin xyz="0. 0. 0." rpy="0. 0. 0."/>
      <geometry>
        <sphere radius="0.019"/>
      </geometry>
    </collision>
    <collision>
      <origin xyz="0. 0. 0.0175" rpy="0. 0. 0."/>
      <geometry>
        <sphere radius="0.017"/>
      </geometry>
    </collision>
    <collision>
      <origin xyz="0. 0. -0.0175" rpy="0. 0. 0."/>
      <geometry>
        <sphere radius="0.017"/>
      </geometry>
    </collision>
  </link>
  <link name="back_left_roller8_link">
    <inertial>
      <origin xyz="0. 0. 0." rpy="0. 0. 0."/>
      <mass value="0.0141372"/>
      <inertia ixx="0." ixy="0." ixz="0." iyy="0." iyz="0." izz="0."/>
    </inertial>
    <visual>
      <origin xyz="-0.00051 0. -0.035 " rpy="0. 0. 0."/>
      <geometry>
        <sphere radius="0.015"/>
      </geometry>
    </visual>
    <visual>
      <origin xyz="-0.00051 0. 0.035 " rpy="0. 0. 0."/>
      <geometry>
        <sphere radius="0.015"/>
      </geometry>
    </visual>
    <visual>
      <origin xyz="0. 0. 0." rpy="0. 0. 0."/>
      <geometry>
        <sphere radius="0.019"/>
      </geometry>
    </visual>
    <visual>
      <origin xyz="0. 0. 0.0175" rpy="0. 0. 0."/>
      <geometry>
        <sphere radius="0.017"/>
      </geometry>
    </visual>
    <visual>
      <origin xyz="0. 0. -0.0175" rpy="0. 0. 0."/>
      <geometry>
        <sphere radius="0.017"/>
      </geometry>
    </visual>
    <collision>
      <origin xyz="-0.00051 0. -0.035 " rpy="0. 0. 0."/>
      <geometry>
        <sphere radius="0.015"/>
      </geometry>
    </collision>
    <collision>
      <origin xyz="-0.00051 0. 0.035 " rpy="0. 0. 0."/>
      <geometry>
        <sphere radius="0.015"/>
      </geometry>
    </collision>
    <collision>
      <origin xyz="0. 0. 0." rpy="0. 0. 0."/>
      <geometry>
        <sphere radius="0.019"/>
      </geometry>
    </collision>
    <collision>
      <origin xyz="0. 0. 0.0175" rpy="0. 0. 0."/>
      <geometry>
        <sphere radius="0.017"/>
      </geometry>
    </collision>
    <collision>
      <origin xyz="0. 0. -0.0175" rpy="0. 0. 0."/>
      <geometry>
        <sphere radius="0.017"/>
      </geometry>
    </collision>
  </link>
  <link name="back_left_roller9_link">
    <inertial>
      <origin xyz="0. 0. 0." rpy="0. 0. 0."/>
      <mass value="0.0141372"/>
      <inertia ixx="0." ixy="0." ixz="0." iyy="0." iyz="0." izz="0."/>
    </inertial>
    <visual>
      <origin xyz="-0.00051 0. -0.035 " rpy="0. 0. 0."/>
      <geometry>
        <sphere radius="0.015"/>
      </geometry>
    </visual>
    <visual>
      <origin xyz="-0.00051 0. 0.035 " rpy="0. 0. 0."/>
      <geometry>
        <sphere radius="0.015"/>
      </geometry>
    </visual>
    <visual>
      <origin xyz="0. 0. 0." rpy="0. 0. 0."/>
      <geometry>
        <sphere radius="0.019"/>
      </geometry>
    </visual>
    <visual>
      <origin xyz="0. 0. 0.0175" rpy="0. 0. 0."/>
      <geometry>
        <sphere radius="0.017"/>
      </geometry>
    </visual>
    <visual>
      <origin xyz="0. 0. -0.0175" rpy="0. 0. 0."/>
      <geometry>
        <sphere radius="0.017"/>
      </geometry>
    </visual>
    <collision>
      <origin xyz="-0.00051 0. -0.035 " rpy="0. 0. 0."/>
      <geometry>
        <sphere radius="0.015"/>
      </geometry>
    </collision>
    <collision>
      <origin xyz="-0.00051 0. 0.035 " rpy="0. 0. 0."/>
      <geometry>
        <sphere radius="0.015"/>
      </geometry>
    </collision>
    <collision>
      <origin xyz="0. 0. 0." rpy="0. 0. 0."/>
      <geometry>
        <sphere radius="0.019"/>
      </geometry>
    </collision>
    <collision>
      <origin xyz="0. 0. 0.0175" rpy="0. 0. 0."/>
      <geometry>
        <sphere radius="0.017"/>
      </geometry>
    </collision>
    <collision>
      <origin xyz="0. 0. -0.0175" rpy="0. 0. 0."/>
      <geometry>
        <sphere radius="0.017"/>
      </geometry>
    </collision>
  </link>
  <link name="back_right_roller10_link">
    <inertial>
      <origin xyz="0. 0. 0." rpy="0. 0. 0."/>
      <mass value="0.0141372"/>
      <inertia ixx="0." ixy="0." ixz="0." iyy="0." iyz="0." izz="0."/>
    </inertial>
    <visual>
      <origin xyz="-0.00051 0. -0.035 " rpy="0. 0. 0."/>
      <geometry>
        <sphere radius="0.015"/>
      </geometry>
    </visual>
    <visual>
      <origin xyz="-0.00051 0. 0.035 " rpy="0. 0. 0."/>
      <geometry>
        <sphere radius="0.015"/>
      </geometry>
    </visual>
    <visual>
      <origin xyz="0. 0. 0." rpy="0. 0. 0."/>
      <geometry>
        <sphere radius="0.019"/>
      </geometry>
    </visual>
    <visual>
      <origin xyz="0. 0. 0.0175" rpy="0. 0. 0."/>
      <geometry>
        <sphere radius="0.017"/>
      </geometry>
    </visual>
    <visual>
      <origin xyz="0. 0. -0.0175" rpy="0. 0. 0."/>
      <geometry>
        <sphere radius="0.017"/>
      </geometry>
    </visual>
    <collision>
      <origin xyz="-0.00051 0. -0.035 " rpy="0. 0. 0."/>
      <geometry>
        <sphere radius="0.015"/>
      </geometry>
    </collision>
    <collision>
      <origin xyz="-0.00051 0. 0.035 " rpy="0. 0. 0."/>
      <geometry>
        <sphere radius="0.015"/>
      </geometry>
    </collision>
    <collision>
      <origin xyz="0. 0. 0." rpy="0. 0. 0."/>
      <geometry>
        <sphere radius="0.019"/>
      </geometry>
    </collision>
    <collision>
      <origin xyz="0. 0. 0.0175" rpy="0. 0. 0."/>
      <geometry>
        <sphere radius="0.017"/>
      </geometry>
    </collision>
    <collision>
      <origin xyz="0. 0. -0.0175" rpy="0. 0. 0."/>
      <geometry>
        <sphere radius="0.017"/>
      </geometry>
    </collision>
  </link>
  <link name="back_right_roller11_link">
    <inertial>
      <origin xyz="0. 0. 0." rpy="0. 0. 0."/>
      <mass value="0.0141372"/>
      <inertia ixx="0." ixy="0." ixz="0." iyy="0." iyz="0." izz="0."/>
    </inertial>
    <visual>
      <origin xyz="-0.00051 0. -0.035 " rpy="0. 0. 0."/>
      <geometry>
        <sphere radius="0.015"/>
      </geometry>
    </visual>
    <visual>
      <origin xyz="-0.00051 0. 0.035 " rpy="0. 0. 0."/>
      <geometry>
        <sphere radius="0.015"/>
      </geometry>
    </visual>
    <visual>
      <origin xyz="0. 0. 0." rpy="0. 0. 0."/>
      <geometry>
        <sphere radius="0.019"/>
      </geometry>
    </visual>
    <visual>
      <origin xyz="0. 0. 0.0175" rpy="0. 0. 0."/>
      <geometry>
        <sphere radius="0.017"/>
      </geometry>
    </visual>
    <visual>
      <origin xyz="0. 0. -0.0175" rpy="0. 0. 0."/>
      <geometry>
        <sphere radius="0.017"/>
      </geometry>
    </visual>
    <collision>
      <origin xyz="-0.00051 0. -0.035 " rpy="0. 0. 0."/>
      <geometry>
        <sphere radius="0.015"/>
      </geometry>
    </collision>
    <collision>
      <origin xyz="-0.00051 0. 0.035 " rpy="0. 0. 0."/>
      <geometry>
        <sphere radius="0.015"/>
      </geometry>
    </collision>
    <collision>
      <origin xyz="0. 0. 0." rpy="0. 0. 0."/>
      <geometry>
        <sphere radius="0.019"/>
      </geometry>
    </collision>
    <collision>
      <origin xyz="0. 0. 0.0175" rpy="0. 0. 0."/>
      <geometry>
        <sphere radius="0.017"/>
      </geometry>
    </collision>
    <collision>
      <origin xyz="0. 0. -0.0175" rpy="0. 0. 0."/>
      <geometry>
        <sphere radius="0.017"/>
      </geometry>
    </collision>
  </link>
  <link name="back_right_roller12_link">
    <inertial>
      <origin xyz="0. 0. 0." rpy="0. 0. 0."/>
      <mass value="0.0141372"/>
      <inertia ixx="0." ixy="0." ixz="0." iyy="0." iyz="0." izz="0."/>
    </inertial>
    <visual>
      <origin xyz="-0.00051 0. -0.035 " rpy="0. 0. 0."/>
      <geometry>
        <sphere radius="0.015"/>
      </geometry>
    </visual>
    <visual>
      <origin xyz="-0.00051 0. 0.035 " rpy="0. 0. 0."/>
      <geometry>
        <sphere radius="0.015"/>
      </geometry>
    </visual>
    <visual>
      <origin xyz="0. 0. 0." rpy="0. 0. 0."/>
      <geometry>
        <sphere radius="0.019"/>
      </geometry>
    </visual>
    <visual>
      <origin xyz="0. 0. 0.0175" rpy="0. 0. 0."/>
      <geometry>
        <sphere radius="0.017"/>
      </geometry>
    </visual>
    <visual>
      <origin xyz="0. 0. -0.0175" rpy="0. 0. 0."/>
      <geometry>
        <sphere radius="0.017"/>
      </geometry>
    </visual>
    <collision>
      <origin xyz="-0.00051 0. -0.035 " rpy="0. 0. 0."/>
      <geometry>
        <sphere radius="0.015"/>
      </geometry>
    </collision>
    <collision>
      <origin xyz="-0.00051 0. 0.035 " rpy="0. 0. 0."/>
      <geometry>
        <sphere radius="0.015"/>
      </geometry>
    </collision>
    <collision>
      <origin xyz="0. 0. 0." rpy="0. 0. 0."/>
      <geometry>
        <sphere radius="0.019"/>
      </geometry>
    </collision>
    <collision>
      <origin xyz="0. 0. 0.0175" rpy="0. 0. 0."/>
      <geometry>
        <sphere radius="0.017"/>
      </geometry>
    </collision>
    <collision>
      <origin xyz="0. 0. -0.0175" rpy="0. 0. 0."/>
      <geometry>
        <sphere radius="0.017"/>
      </geometry>
    </collision>
  </link>
  <link name="back_right_roller1_link">
    <inertial>
      <origin xyz="0. 0. 0." rpy="0. 0. 0."/>
      <mass value="0.0141372"/>
      <inertia ixx="0." ixy="0." ixz="0." iyy="0." iyz="0." izz="0."/>
    </inertial>
    <visual>
      <origin xyz="-0.00051 0. -0.035 " rpy="0. 0. 0."/>
      <geometry>
        <sphere radius="0.015"/>
      </geometry>
    </visual>
    <visual>
      <origin xyz="-0.00051 0. 0.035 " rpy="0. 0. 0."/>
      <geometry>
        <sphere radius="0.015"/>
      </geometry>
    </visual>
    <visual>
      <origin xyz="0. 0. 0." rpy="0. 0. 0."/>
      <geometry>
        <sphere radius="0.019"/>
      </geometry>
    </visual>
    <visual>
      <origin xyz="0. 0. 0.0175" rpy="0. 0. 0."/>
      <geometry>
        <sphere radius="0.017"/>
      </geometry>
    </visual>
    <visual>
      <origin xyz="0. 0. -0.0175" rpy="0. 0. 0."/>
      <geometry>
        <sphere radius="0.017"/>
      </geometry>
    </visual>
    <collision>
      <origin xyz="-0.00051 0. -0.035 " rpy="0. 0. 0."/>
      <geometry>
        <sphere radius="0.015"/>
      </geometry>
    </collision>
    <collision>
      <origin xyz="-0.00051 0. 0.035 " rpy="0. 0. 0."/>
      <geometry>
        <sphere radius="0.015"/>
      </geometry>
    </collision>
    <collision>
      <origin xyz="0. 0. 0." rpy="0. 0. 0."/>
      <geometry>
        <sphere radius="0.019"/>
      </geometry>
    </collision>
    <collision>
      <origin xyz="0. 0. 0.0175" rpy="0. 0. 0."/>
      <geometry>
        <sphere radius="0.017"/>
      </geometry>
    </collision>
    <collision>
      <origin xyz="0. 0. -0.0175" rpy="0. 0. 0."/>
      <geometry>
        <sphere radius="0.017"/>
      </geometry>
    </collision>
  </link>
  <link name="back_right_roller2_link">
    <inertial>
      <origin xyz="0. 0. 0." rpy="0. 0. 0."/>
      <mass value="0.0141372"/>
      <inertia ixx="0." ixy="0." ixz="0." iyy="0." iyz="0." izz="0."/>
    </inertial>
    <visual>
      <origin xyz="-0.00051 0. -0.035 " rpy="0. 0. 0."/>
      <geometry>
        <sphere radius="0.015"/>
      </geometry>
    </visual>
    <visual>
      <origin xyz="-0.00051 0. 0.035 " rpy="0. 0. 0."/>
      <geometry>
        <sphere radius="0.015"/>
      </geometry>
    </visual>
    <visual>
      <origin xyz="0. 0. 0." rpy="0. 0. 0."/>
      <geometry>
        <sphere radius="0.019"/>
      </geometry>
    </visual>
    <visual>
      <origin xyz="0. 0. 0.0175" rpy="0. 0. 0."/>
      <geometry>
        <sphere radius="0.017"/>
      </geometry>
    </visual>
    <visual>
      <origin xyz="0. 0. -0.0175" rpy="0. 0. 0."/>
      <geometry>
        <sphere radius="0.017"/>
      </geometry>
    </visual>
    <collision>
      <origin xyz="-0.00051 0. -0.035 " rpy="0. 0. 0."/>
      <geometry>
        <sphere radius="0.015"/>
      </geometry>
    </collision>
    <collision>
      <origin xyz="-0.00051 0. 0.035 " rpy="0. 0. 0."/>
      <geometry>
        <sphere radius="0.015"/>
      </geometry>
    </collision>
    <collision>
      <origin xyz="0. 0. 0." rpy="0. 0. 0."/>
      <geometry>
        <sphere radius="0.019"/>
      </geometry>
    </collision>
    <collision>
      <origin xyz="0. 0. 0.0175" rpy="0. 0. 0."/>
      <geometry>
        <sphere radius="0.017"/>
      </geometry>
    </collision>
    <collision>
      <origin xyz="0. 0. -0.0175" rpy="0. 0. 0."/>
      <geometry>
        <sphere radius="0.017"/>
      </geometry>
    </collision>
  </link>
  <link name="back_right_roller3_link">
    <inertial>
      <origin xyz="0. 0. 0." rpy="0. 0. 0."/>
      <mass value="0.0141372"/>
      <inertia ixx="0." ixy="0." ixz="0." iyy="0." iyz="0." izz="0."/>
    </inertial>
    <visual>
      <origin xyz="-0.00051 0. -0.035 " rpy="0. 0. 0."/>
      <geometry>
        <sphere radius="0.015"/>
      </geometry>
    </visual>
    <visual>
      <origin xyz="-0.00051 0. 0.035 " rpy="0. 0. 0."/>
      <geometry>
        <sphere radius="0.015"/>
      </geometry>
    </visual>
    <visual>
      <origin xyz="0. 0. 0." rpy="0. 0. 0."/>
      <geometry>
        <sphere radius="0.019"/>
      </geometry>
    </visual>
    <visual>
      <origin xyz="0. 0. 0.0175" rpy="0. 0. 0."/>
      <geometry>
        <sphere radius="0.017"/>
      </geometry>
    </visual>
    <visual>
      <origin xyz="0. 0. -0.0175" rpy="0. 0. 0."/>
      <geometry>
        <sphere radius="0.017"/>
      </geometry>
    </visual>
    <collision>
      <origin xyz="-0.00051 0. -0.035 " rpy="0. 0. 0."/>
      <geometry>
        <sphere radius="0.015"/>
      </geometry>
    </collision>
    <collision>
      <origin xyz="-0.00051 0. 0.035 " rpy="0. 0. 0."/>
      <geometry>
        <sphere radius="0.015"/>
      </geometry>
    </collision>
    <collision>
      <origin xyz="0. 0. 0." rpy="0. 0. 0."/>
      <geometry>
        <sphere radius="0.019"/>
      </geometry>
    </collision>
    <collision>
      <origin xyz="0. 0. 0.0175" rpy="0. 0. 0."/>
      <geometry>
        <sphere radius="0.017"/>
      </geometry>
    </collision>
    <collision>
      <origin xyz="0. 0. -0.0175" rpy="0. 0. 0."/>
      <geometry>
        <sphere radius="0.017"/>
      </geometry>
    </collision>
  </link>
  <link name="back_right_roller4_link">
    <inertial>
      <origin xyz="0. 0. 0." rpy="0. 0. 0."/>
      <mass value="0.0141372"/>
      <inertia ixx="0." ixy="0." ixz="0." iyy="0." iyz="0." izz="0."/>
    </inertial>
    <visual>
      <origin xyz="-0.00051 0. -0.035 " rpy="0. 0. 0."/>
      <geometry>
        <sphere radius="0.015"/>
      </geometry>
    </visual>
    <visual>
      <origin xyz="-0.00051 0. 0.035 " rpy="0. 0. 0."/>
      <geometry>
        <sphere radius="0.015"/>
      </geometry>
    </visual>
    <visual>
      <origin xyz="0. 0. 0." rpy="0. 0. 0."/>
      <geometry>
        <sphere radius="0.019"/>
      </geometry>
    </visual>
    <visual>
      <origin xyz="0. 0. 0.0175" rpy="0. 0. 0."/>
      <geometry>
        <sphere radius="0.017"/>
      </geometry>
    </visual>
    <visual>
      <origin xyz="0. 0. -0.0175" rpy="0. 0. 0."/>
      <geometry>
        <sphere radius="0.017"/>
      </geometry>
    </visual>
    <collision>
      <origin xyz="-0.00051 0. -0.035 " rpy="0. 0. 0."/>
      <geometry>
        <sphere radius="0.015"/>
      </geometry>
    </collision>
    <collision>
      <origin xyz="-0.00051 0. 0.035 " rpy="0. 0. 0."/>
      <geometry>
        <sphere radius="0.015"/>
      </geometry>
    </collision>
    <collision>
      <origin xyz="0. 0. 0." rpy="0. 0. 0."/>
      <geometry>
        <sphere radius="0.019"/>
      </geometry>
    </collision>
    <collision>
      <origin xyz="0. 0. 0.0175" rpy="0. 0. 0."/>
      <geometry>
        <sphere radius="0.017"/>
      </geometry>
    </collision>
    <collision>
      <origin xyz="0. 0. -0.0175" rpy="0. 0. 0."/>
      <geometry>
        <sphere radius="0.017"/>
      </geometry>
    </collision>
  </link>
  <link name="back_right_roller5_link">
    <inertial>
      <origin xyz="0. 0. 0." rpy="0. 0. 0."/>
      <mass value="0.0141372"/>
      <inertia ixx="0." ixy="0." ixz="0." iyy="0." iyz="0." izz="0."/>
    </inertial>
    <visual>
      <origin xyz="-0.00051 0. -0.035 " rpy="0. 0. 0."/>
      <geometry>
        <sphere radius="0.015"/>
      </geometry>
    </visual>
    <visual>
      <origin xyz="-0.00051 0. 0.035 " rpy="0. 0. 0."/>
      <geometry>
        <sphere radius="0.015"/>
      </geometry>
    </visual>
    <visual>
      <origin xyz="0. 0. 0." rpy="0. 0. 0."/>
      <geometry>
        <sphere radius="0.019"/>
      </geometry>
    </visual>
    <visual>
      <origin xyz="0. 0. 0.0175" rpy="0. 0. 0."/>
      <geometry>
        <sphere radius="0.017"/>
      </geometry>
    </visual>
    <visual>
      <origin xyz="0. 0. -0.0175" rpy="0. 0. 0."/>
      <geometry>
        <sphere radius="0.017"/>
      </geometry>
    </visual>
    <collision>
      <origin xyz="-0.00051 0. -0.035 " rpy="0. 0. 0."/>
      <geometry>
        <sphere radius="0.015"/>
      </geometry>
    </collision>
    <collision>
      <origin xyz="-0.00051 0. 0.035 " rpy="0. 0. 0."/>
      <geometry>
        <sphere radius="0.015"/>
      </geometry>
    </collision>
    <collision>
      <origin xyz="0. 0. 0." rpy="0. 0. 0."/>
      <geometry>
        <sphere radius="0.019"/>
      </geometry>
    </collision>
    <collision>
      <origin xyz="0. 0. 0.0175" rpy="0. 0. 0."/>
      <geometry>
        <sphere radius="0.017"/>
      </geometry>
    </collision>
    <collision>
      <origin xyz="0. 0. -0.0175" rpy="0. 0. 0."/>
      <geometry>
        <sphere radius="0.017"/>
      </geometry>
    </collision>
  </link>
  <link name="back_right_roller6_link">
    <inertial>
      <origin xyz="0. 0. 0." rpy="0. 0. 0."/>
      <mass value="0.0141372"/>
      <inertia ixx="0." ixy="0." ixz="0." iyy="0." iyz="0." izz="0."/>
    </inertial>
    <visual>
      <origin xyz="-0.00051 0. -0.035 " rpy="0. 0. 0."/>
      <geometry>
        <sphere radius="0.015"/>
      </geometry>
    </visual>
    <visual>
      <origin xyz="-0.00051 0. 0.035 " rpy="0. 0. 0."/>
      <geometry>
        <sphere radius="0.015"/>
      </geometry>
    </visual>
    <visual>
      <origin xyz="0. 0. 0." rpy="0. 0. 0."/>
      <geometry>
        <sphere radius="0.019"/>
      </geometry>
    </visual>
    <visual>
      <origin xyz="0. 0. 0.0175" rpy="0. 0. 0."/>
      <geometry>
        <sphere radius="0.017"/>
      </geometry>
    </visual>
    <visual>
      <origin xyz="0. 0. -0.0175" rpy="0. 0. 0."/>
      <geometry>
        <sphere radius="0.017"/>
      </geometry>
    </visual>
    <collision>
      <origin xyz="-0.00051 0. -0.035 " rpy="0. 0. 0."/>
      <geometry>
        <sphere radius="0.015"/>
      </geometry>
    </collision>
    <collision>
      <origin xyz="-0.00051 0. 0.035 " rpy="0. 0. 0."/>
      <geometry>
        <sphere radius="0.015"/>
      </geometry>
    </collision>
    <collision>
      <origin xyz="0. 0. 0." rpy="0. 0. 0."/>
      <geometry>
        <sphere radius="0.019"/>
      </geometry>
    </collision>
    <collision>
      <origin xyz="0. 0. 0.0175" rpy="0. 0. 0."/>
      <geometry>
        <sphere radius="0.017"/>
      </geometry>
    </collision>
    <collision>
      <origin xyz="0. 0. -0.0175" rpy="0. 0. 0."/>
      <geometry>
        <sphere radius="0.017"/>
      </geometry>
    </collision>
  </link>
  <link name="back_right_roller7_link">
    <inertial>
      <origin xyz="0. 0. 0." rpy="0. 0. 0."/>
      <mass value="0.0141372"/>
      <inertia ixx="0." ixy="0." ixz="0." iyy="0." iyz="0." izz="0."/>
    </inertial>
    <visual>
      <origin xyz="-0.00051 0. -0.035 " rpy="0. 0. 0."/>
      <geometry>
        <sphere radius="0.015"/>
      </geometry>
    </visual>
    <visual>
      <origin xyz="-0.00051 0. 0.035 " rpy="0. 0. 0."/>
      <geometry>
        <sphere radius="0.015"/>
      </geometry>
    </visual>
    <visual>
      <origin xyz="0. 0. 0." rpy="0. 0. 0."/>
      <geometry>
        <sphere radius="0.019"/>
      </geometry>
    </visual>
    <visual>
      <origin xyz="0. 0. 0.0175" rpy="0. 0. 0."/>
      <geometry>
        <sphere radius="0.017"/>
      </geometry>
    </visual>
    <visual>
      <origin xyz="0. 0. -0.0175" rpy="0. 0. 0."/>
      <geometry>
        <sphere radius="0.017"/>
      </geometry>
    </visual>
    <collision>
      <origin xyz="-0.00051 0. -0.035 " rpy="0. 0. 0."/>
      <geometry>
        <sphere radius="0.015"/>
      </geometry>
    </collision>
    <collision>
      <origin xyz="-0.00051 0. 0.035 " rpy="0. 0. 0."/>
      <geometry>
        <sphere radius="0.015"/>
      </geometry>
    </collision>
    <collision>
      <origin xyz="0. 0. 0." rpy="0. 0. 0."/>
      <geometry>
        <sphere radius="0.019"/>
      </geometry>
    </collision>
    <collision>
      <origin xyz="0. 0. 0.0175" rpy="0. 0. 0."/>
      <geometry>
        <sphere radius="0.017"/>
      </geometry>
    </collision>
    <collision>
      <origin xyz="0. 0. -0.0175" rpy="0. 0. 0."/>
      <geometry>
        <sphere radius="0.017"/>
      </geometry>
    </collision>
  </link>
  <link name="back_right_roller8_link">
    <inertial>
      <origin xyz="0. 0. 0." rpy="0. 0. 0."/>
      <mass value="0.0141372"/>
      <inertia ixx="0." ixy="0." ixz="0." iyy="0." iyz="0." izz="0."/>
    </inertial>
    <visual>
      <origin xyz="-0.00051 0. -0.035 " rpy="0. 0. 0."/>
      <geometry>
        <sphere radius="0.015"/>
      </geometry>
    </visual>
    <visual>
      <origin xyz="-0.00051 0. 0.035 " rpy="0. 0. 0."/>
      <geometry>
        <sphere radius="0.015"/>
      </geometry>
    </visual>
    <visual>
      <origin xyz="0. 0. 0." rpy="0. 0. 0."/>
      <geometry>
        <sphere radius="0.019"/>
      </geometry>
    </visual>
    <visual>
      <origin xyz="0. 0. 0.0175" rpy="0. 0. 0."/>
      <geometry>
        <sphere radius="0.017"/>
      </geometry>
    </visual>
    <visual>
      <origin xyz="0. 0. -0.0175" rpy="0. 0. 0."/>
      <geometry>
        <sphere radius="0.017"/>
      </geometry>
    </visual>
    <collision>
      <origin xyz="-0.00051 0. -0.035 " rpy="0. 0. 0."/>
      <geometry>
        <sphere radius="0.015"/>
      </geometry>
    </collision>
    <collision>
      <origin xyz="-0.00051 0. 0.035 " rpy="0. 0. 0."/>
      <geometry>
        <sphere radius="0.015"/>
      </geometry>
    </collision>
    <collision>
      <origin xyz="0. 0. 0." rpy="0. 0. 0."/>
      <geometry>
        <sphere radius="0.019"/>
      </geometry>
    </collision>
    <collision>
      <origin xyz="0. 0. 0.0175" rpy="0. 0. 0."/>
      <geometry>
        <sphere radius="0.017"/>
      </geometry>
    </collision>
    <collision>
      <origin xyz="0. 0. -0.0175" rpy="0. 0. 0."/>
      <geometry>
        <sphere radius="0.017"/>
      </geometry>
    </collision>
  </link>
  <link name="back_right_roller9_link">
    <inertial>
      <origin xyz="0. 0. 0." rpy="0. 0. 0."/>
      <mass value="0.0141372"/>
      <inertia ixx="0." ixy="0." ixz="0." iyy="0." iyz="0." izz="0."/>
    </inertial>
    <visual>
      <origin xyz="-0.00051 0. -0.035 " rpy="0. 0. 0."/>
      <geometry>
        <sphere radius="0.015"/>
      </geometry>
    </visual>
    <visual>
      <origin xyz="-0.00051 0. 0.035 " rpy="0. 0. 0."/>
      <geometry>
        <sphere radius="0.015"/>
      </geometry>
    </visual>
    <visual>
      <origin xyz="0. 0. 0." rpy="0. 0. 0."/>
      <geometry>
        <sphere radius="0.019"/>
      </geometry>
    </visual>
    <visual>
      <origin xyz="0. 0. 0.0175" rpy="0. 0. 0."/>
      <geometry>
        <sphere radius="0.017"/>
      </geometry>
    </visual>
    <visual>
      <origin xyz="0. 0. -0.0175" rpy="0. 0. 0."/>
      <geometry>
        <sphere radius="0.017"/>
      </geometry>
    </visual>
    <collision>
      <origin xyz="-0.00051 0. -0.035 " rpy="0. 0. 0."/>
      <geometry>
        <sphere radius="0.015"/>
      </geometry>
    </collision>
    <collision>
      <origin xyz="-0.00051 0. 0.035 " rpy="0. 0. 0."/>
      <geometry>
        <sphere radius="0.015"/>
      </geometry>
    </collision>
    <collision>
      <origin xyz="0. 0. 0." rpy="0. 0. 0."/>
      <geometry>
        <sphere radius="0.019"/>
      </geometry>
    </collision>
    <collision>
      <origin xyz="0. 0. 0.0175" rpy="0. 0. 0."/>
      <geometry>
        <sphere radius="0.017"/>
      </geometry>
    </collision>
    <collision>
      <origin xyz="0. 0. -0.0175" rpy="0. 0. 0."/>
      <geometry>
        <sphere radius="0.017"/>
      </geometry>
    </collision>
  </link>
  <link name="base_link">
    <inertial>
      <origin xyz="0. 0. 0." rpy="0. 0. 0."/>
      <mass value="125."/>
      <inertia ixx="0." ixy="0." ixz="0." iyy="0." iyz="0." izz="0."/>
    </inertial>
    <visual>
      <origin xyz="0. 0. 0." rpy="0. 0. 0."/>
      <geometry>
        <mesh filename="package://robot_description/meshes/base_link_visuals.obj" scale="1. 1. 1."/>
      </geometry>
    </visual>
    <collision>
      <origin xyz="0. 0. 0." rpy="0. 0. 0."/>
      <geometry>
        <mesh filename="package://robot_description/meshes/base_link_visuals.obj" scale="1. 1. 1."/>
      </geometry>
    </collision>
  </link>
  <link name="franka_panda_hand">
    <inertial>
      <origin xyz="0. 0. 0." rpy="0. 0. 0."/>
      <mass value="0.5583305"/>
      <inertia ixx="0." ixy="0." ixz="0." iyy="0." iyz="0." izz="0."/>
    </inertial>
    <visual>
      <origin xyz="0. 0. 0." rpy="0. 0. 0."/>
      <geometry>
        <mesh filename="package://robot_description/meshes/ID234_001.obj" scale="1. 1. 1."/>
      </geometry>
    </visual>
    <visual>
      <origin xyz="0. 0. 0." rpy="0. 0. 0."/>
      <geometry>
        <mesh filename="package://robot_description/meshes/ID234_001frA.obj" scale="1. 1. 1."/>
      </geometry>
    </visual>
    <visual>
      <origin xyz="0. 0. 0." rpy="0. 0. 0."/>
      <geometry>
        <mesh filename="package://robot_description/meshes/ID234_001jEI.obj" scale="1. 1. 1."/>
      </geometry>
    </visual>
    <visual>
      <origin xyz="0. 0. 0." rpy="0. 0. 0."/>
      <geometry>
        <mesh filename="package://robot_description/meshes/ID234_001m4u.obj" scale="1. 1. 1."/>
      </geometry>
    </visual>
    <visual>
      <origin xyz="0. 0. 0." rpy="0. 0. 0.0000002"/>
      <geometry>
        <mesh filename="package://robot_description/meshes/ID4_000.obj" scale="1. 1. 1."/>
      </geometry>
    </visual>
    <visual>
      <origin xyz="0. 0. 0." rpy="0. 0. 0.0000002"/>
      <geometry>
        <mesh filename="package://robot_description/meshes/ID4_000frA.obj" scale="1. 1. 1."/>
      </geometry>
    </visual>
    <visual>
      <origin xyz="0. 0. 0." rpy="0. 0. 0.0000002"/>
      <geometry>
        <mesh filename="package://robot_description/meshes/ID4_000jEI.obj" scale="1. 1. 1."/>
      </geometry>
    </visual>
    <visual>
      <origin xyz="0. 0. 0." rpy="0. 0. 0.0000002"/>
      <geometry>
        <mesh filename="package://robot_description/meshes/ID4_000m4u.obj" scale="1. 1. 1."/>
      </geometry>
    </visual>
    <collision>
      <origin xyz="0. 0. 0." rpy="0. 0. 0."/>
      <geometry>
        <mesh filename="package://robot_description/meshes/ID234_001frA.obj" scale="1. 1. 1."/>
      </geometry>
    </collision>
    <collision>
      <origin xyz="0. 0. 0." rpy="0. 0. 0."/>
      <geometry>
        <mesh filename="package://robot_description/meshes/ID234_001m4u.obj" scale="1. 1. 1."/>
      </geometry>
    </collision>
    <collision>
      <origin xyz="0. 0. 0." rpy="0. 0. 0.0000002"/>
      <geometry>
        <mesh filename="package://robot_description/meshes/ID4_000.obj" scale="1. 1. 1."/>
      </geometry>
    </collision>
    <collision>
      <origin xyz="0. 0. 0." rpy="0. 0. 0.0000002"/>
      <geometry>
        <mesh filename="package://robot_description/meshes/ID4_000m4u.obj" scale="1. 1. 1."/>
      </geometry>
    </collision>
  </link>
  <link name="front_left_roller10_link">
    <inertial>
      <origin xyz="0. 0. 0." rpy="0. 0. 0."/>
      <mass value="0.0141372"/>
      <inertia ixx="0." ixy="0." ixz="0." iyy="0." iyz="0." izz="0."/>
    </inertial>
    <visual>
      <origin xyz="-0.00051 0. -0.035 " rpy="0. 0. 0."/>
      <geometry>
        <sphere radius="0.015"/>
      </geometry>
    </visual>
    <visual>
      <origin xyz="-0.00051 0. 0.035 " rpy="0. 0. 0."/>
      <geometry>
        <sphere radius="0.015"/>
      </geometry>
    </visual>
    <visual>
      <origin xyz="0. 0. 0." rpy="0. 0. 0."/>
      <geometry>
        <sphere radius="0.019"/>
      </geometry>
    </visual>
    <visual>
      <origin xyz="0. 0. 0.0175" rpy="0. 0. 0."/>
      <geometry>
        <sphere radius="0.017"/>
      </geometry>
    </visual>
    <visual>
      <origin xyz="0. 0. -0.0175" rpy="0. 0. 0."/>
      <geometry>
        <sphere radius="0.017"/>
      </geometry>
    </visual>
    <collision>
      <origin xyz="-0.00051 0. -0.035 " rpy="0. 0. 0."/>
      <geometry>
        <sphere radius="0.015"/>
      </geometry>
    </collision>
    <collision>
      <origin xyz="-0.00051 0. 0.035 " rpy="0. 0. 0."/>
      <geometry>
        <sphere radius="0.015"/>
      </geometry>
    </collision>
    <collision>
      <origin xyz="0. 0. 0." rpy="0. 0. 0."/>
      <geometry>
        <sphere radius="0.019"/>
      </geometry>
    </collision>
    <collision>
      <origin xyz="0. 0. 0.0175" rpy="0. 0. 0."/>
      <geometry>
        <sphere radius="0.017"/>
      </geometry>
    </collision>
    <collision>
      <origin xyz="0. 0. -0.0175" rpy="0. 0. 0."/>
      <geometry>
        <sphere radius="0.017"/>
      </geometry>
    </collision>
  </link>
  <link name="front_left_roller11_link">
    <inertial>
      <origin xyz="0. 0. 0." rpy="0. 0. 0."/>
      <mass value="0.0141372"/>
      <inertia ixx="0." ixy="0." ixz="0." iyy="0." iyz="0." izz="0."/>
    </inertial>
    <visual>
      <origin xyz="-0.00051 0. -0.035 " rpy="0. 0. 0."/>
      <geometry>
        <sphere radius="0.015"/>
      </geometry>
    </visual>
    <visual>
      <origin xyz="-0.00051 0. 0.035 " rpy="0. 0. 0."/>
      <geometry>
        <sphere radius="0.015"/>
      </geometry>
    </visual>
    <visual>
      <origin xyz="0. 0. 0." rpy="0. 0. 0."/>
      <geometry>
        <sphere radius="0.019"/>
      </geometry>
    </visual>
    <visual>
      <origin xyz="0. 0. 0.0175" rpy="0. 0. 0."/>
      <geometry>
        <sphere radius="0.017"/>
      </geometry>
    </visual>
    <visual>
      <origin xyz="0. 0. -0.0175" rpy="0. 0. 0."/>
      <geometry>
        <sphere radius="0.017"/>
      </geometry>
    </visual>
    <collision>
      <origin xyz="-0.00051 0. -0.035 " rpy="0. 0. 0."/>
      <geometry>
        <sphere radius="0.015"/>
      </geometry>
    </collision>
    <collision>
      <origin xyz="-0.00051 0. 0.035 " rpy="0. 0. 0."/>
      <geometry>
        <sphere radius="0.015"/>
      </geometry>
    </collision>
    <collision>
      <origin xyz="0. 0. 0." rpy="0. 0. 0."/>
      <geometry>
        <sphere radius="0.019"/>
      </geometry>
    </collision>
    <collision>
      <origin xyz="0. 0. 0.0175" rpy="0. 0. 0."/>
      <geometry>
        <sphere radius="0.017"/>
      </geometry>
    </collision>
    <collision>
      <origin xyz="0. 0. -0.0175" rpy="0. 0. 0."/>
      <geometry>
        <sphere radius="0.017"/>
      </geometry>
    </collision>
  </link>
  <link name="front_left_roller12_link">
    <inertial>
      <origin xyz="0. 0. 0." rpy="0. 0. 0."/>
      <mass value="0.0141372"/>
      <inertia ixx="0." ixy="0." ixz="0." iyy="0." iyz="0." izz="0."/>
    </inertial>
    <visual>
      <origin xyz="-0.00051 0. -0.035 " rpy="0. 0. 0."/>
      <geometry>
        <sphere radius="0.015"/>
      </geometry>
    </visual>
    <visual>
      <origin xyz="-0.00051 0. 0.035 " rpy="0. 0. 0."/>
      <geometry>
        <sphere radius="0.015"/>
      </geometry>
    </visual>
    <visual>
      <origin xyz="0. 0. 0." rpy="0. 0. 0."/>
      <geometry>
        <sphere radius="0.019"/>
      </geometry>
    </visual>
    <visual>
      <origin xyz="0. 0. 0.0175" rpy="0. 0. 0."/>
      <geometry>
        <sphere radius="0.017"/>
      </geometry>
    </visual>
    <visual>
      <origin xyz="0. 0. -0.0175" rpy="0. 0. 0."/>
      <geometry>
        <sphere radius="0.017"/>
      </geometry>
    </visual>
    <collision>
      <origin xyz="-0.00051 0. -0.035 " rpy="0. 0. 0."/>
      <geometry>
        <sphere radius="0.015"/>
      </geometry>
    </collision>
    <collision>
      <origin xyz="-0.00051 0. 0.035 " rpy="0. 0. 0."/>
      <geometry>
        <sphere radius="0.015"/>
      </geometry>
    </collision>
    <collision>
      <origin xyz="0. 0. 0." rpy="0. 0. 0."/>
      <geometry>
        <sphere radius="0.019"/>
      </geometry>
    </collision>
    <collision>
      <origin xyz="0. 0. 0.0175" rpy="0. 0. 0."/>
      <geometry>
        <sphere radius="0.017"/>
      </geometry>
    </collision>
    <collision>
      <origin xyz="0. 0. -0.0175" rpy="0. 0. 0."/>
      <geometry>
        <sphere radius="0.017"/>
      </geometry>
    </collision>
  </link>
  <link name="front_left_roller1_link">
    <inertial>
      <origin xyz="0. 0. 0." rpy="0. 0. 0."/>
      <mass value="0.0141372"/>
      <inertia ixx="0." ixy="0." ixz="0." iyy="0." iyz="0." izz="0."/>
    </inertial>
    <visual>
      <origin xyz="-0.00051 0. -0.035 " rpy="0. 0. 0."/>
      <geometry>
        <sphere radius="0.015"/>
      </geometry>
    </visual>
    <visual>
      <origin xyz="-0.00051 0. 0.035 " rpy="0. 0. 0."/>
      <geometry>
        <sphere radius="0.015"/>
      </geometry>
    </visual>
    <visual>
      <origin xyz="0. 0. 0." rpy="0. 0. 0."/>
      <geometry>
        <sphere radius="0.019"/>
      </geometry>
    </visual>
    <visual>
      <origin xyz="0. 0. 0.0175" rpy="0. 0. 0."/>
      <geometry>
        <sphere radius="0.017"/>
      </geometry>
    </visual>
    <visual>
      <origin xyz="0. 0. -0.0175" rpy="0. 0. 0."/>
      <geometry>
        <sphere radius="0.017"/>
      </geometry>
    </visual>
    <collision>
      <origin xyz="-0.00051 0. -0.035 " rpy="0. 0. 0."/>
      <geometry>
        <sphere radius="0.015"/>
      </geometry>
    </collision>
    <collision>
      <origin xyz="-0.00051 0. 0.035 " rpy="0. 0. 0."/>
      <geometry>
        <sphere radius="0.015"/>
      </geometry>
    </collision>
    <collision>
      <origin xyz="0. 0. 0." rpy="0. 0. 0."/>
      <geometry>
        <sphere radius="0.019"/>
      </geometry>
    </collision>
    <collision>
      <origin xyz="0. 0. 0.0175" rpy="0. 0. 0."/>
      <geometry>
        <sphere radius="0.017"/>
      </geometry>
    </collision>
    <collision>
      <origin xyz="0. 0. -0.0175" rpy="0. 0. 0."/>
      <geometry>
        <sphere radius="0.017"/>
      </geometry>
    </collision>
  </link>
  <link name="front_left_roller2_link">
    <inertial>
      <origin xyz="0. 0. 0." rpy="0. 0. 0."/>
      <mass value="0.0141372"/>
      <inertia ixx="0." ixy="0." ixz="0." iyy="0." iyz="0." izz="0."/>
    </inertial>
    <visual>
      <origin xyz="-0.00051 0. -0.035 " rpy="0. 0. 0."/>
      <geometry>
        <sphere radius="0.015"/>
      </geometry>
    </visual>
    <visual>
      <origin xyz="-0.00051 0. 0.035 " rpy="0. 0. 0."/>
      <geometry>
        <sphere radius="0.015"/>
      </geometry>
    </visual>
    <visual>
      <origin xyz="0. 0. 0." rpy="0. 0. 0."/>
      <geometry>
        <sphere radius="0.019"/>
      </geometry>
    </visual>
    <visual>
      <origin xyz="0. 0. 0.0175" rpy="0. 0. 0."/>
      <geometry>
        <sphere radius="0.017"/>
      </geometry>
    </visual>
    <visual>
      <origin xyz="0. 0. -0.0175" rpy="0. 0. 0."/>
      <geometry>
        <sphere radius="0.017"/>
      </geometry>
    </visual>
    <collision>
      <origin xyz="-0.00051 0. -0.035 " rpy="0. 0. 0."/>
      <geometry>
        <sphere radius="0.015"/>
      </geometry>
    </collision>
    <collision>
      <origin xyz="-0.00051 0. 0.035 " rpy="0. 0. 0."/>
      <geometry>
        <sphere radius="0.015"/>
      </geometry>
    </collision>
    <collision>
      <origin xyz="0. 0. 0." rpy="0. 0. 0."/>
      <geometry>
        <sphere radius="0.019"/>
      </geometry>
    </collision>
    <collision>
      <origin xyz="0. 0. 0.0175" rpy="0. 0. 0."/>
      <geometry>
        <sphere radius="0.017"/>
      </geometry>
    </collision>
    <collision>
      <origin xyz="0. 0. -0.0175" rpy="0. 0. 0."/>
      <geometry>
        <sphere radius="0.017"/>
      </geometry>
    </collision>
  </link>
  <link name="front_left_roller3_link">
    <inertial>
      <origin xyz="0. 0. 0." rpy="0. 0. 0."/>
      <mass value="0.0141372"/>
      <inertia ixx="0." ixy="0." ixz="0." iyy="0." iyz="0." izz="0."/>
    </inertial>
    <visual>
      <origin xyz="-0.00051 0. -0.035 " rpy="0. 0. 0."/>
      <geometry>
        <sphere radius="0.015"/>
      </geometry>
    </visual>
    <visual>
      <origin xyz="-0.00051 0. 0.035 " rpy="0. 0. 0."/>
      <geometry>
        <sphere radius="0.015"/>
      </geometry>
    </visual>
    <visual>
      <origin xyz="0. 0. 0." rpy="0. 0. 0."/>
      <geometry>
        <sphere radius="0.019"/>
      </geometry>
    </visual>
    <visual>
      <origin xyz="0. 0. 0.0175" rpy="0. 0. 0."/>
      <geometry>
        <sphere radius="0.017"/>
      </geometry>
    </visual>
    <visual>
      <origin xyz="0. 0. -0.0175" rpy="0. 0. 0."/>
      <geometry>
        <sphere radius="0.017"/>
      </geometry>
    </visual>
    <collision>
      <origin xyz="-0.00051 0. -0.035 " rpy="0. 0. 0."/>
      <geometry>
        <sphere radius="0.015"/>
      </geometry>
    </collision>
    <collision>
      <origin xyz="-0.00051 0. 0.035 " rpy="0. 0. 0."/>
      <geometry>
        <sphere radius="0.015"/>
      </geometry>
    </collision>
    <collision>
      <origin xyz="0. 0. 0." rpy="0. 0. 0."/>
      <geometry>
        <sphere radius="0.019"/>
      </geometry>
    </collision>
    <collision>
      <origin xyz="0. 0. 0.0175" rpy="0. 0. 0."/>
      <geometry>
        <sphere radius="0.017"/>
      </geometry>
    </collision>
    <collision>
      <origin xyz="0. 0. -0.0175" rpy="0. 0. 0."/>
      <geometry>
        <sphere radius="0.017"/>
      </geometry>
    </collision>
  </link>
  <link name="front_left_roller4_link">
    <inertial>
      <origin xyz="0. 0. 0." rpy="0. 0. 0."/>
      <mass value="0.0141372"/>
      <inertia ixx="0." ixy="0." ixz="0." iyy="0." iyz="0." izz="0."/>
    </inertial>
    <visual>
      <origin xyz="-0.00051 0. -0.035 " rpy="0. 0. 0."/>
      <geometry>
        <sphere radius="0.015"/>
      </geometry>
    </visual>
    <visual>
      <origin xyz="-0.00051 0. 0.035 " rpy="0. 0. 0."/>
      <geometry>
        <sphere radius="0.015"/>
      </geometry>
    </visual>
    <visual>
      <origin xyz="0. 0. 0." rpy="0. 0. 0."/>
      <geometry>
        <sphere radius="0.019"/>
      </geometry>
    </visual>
    <visual>
      <origin xyz="0. 0. 0.0175" rpy="0. 0. 0."/>
      <geometry>
        <sphere radius="0.017"/>
      </geometry>
    </visual>
    <visual>
      <origin xyz="0. 0. -0.0175" rpy="0. 0. 0."/>
      <geometry>
        <sphere radius="0.017"/>
      </geometry>
    </visual>
    <collision>
      <origin xyz="-0.00051 0. -0.035 " rpy="0. 0. 0."/>
      <geometry>
        <sphere radius="0.015"/>
      </geometry>
    </collision>
    <collision>
      <origin xyz="-0.00051 0. 0.035 " rpy="0. 0. 0."/>
      <geometry>
        <sphere radius="0.015"/>
      </geometry>
    </collision>
    <collision>
      <origin xyz="0. 0. 0." rpy="0. 0. 0."/>
      <geometry>
        <sphere radius="0.019"/>
      </geometry>
    </collision>
    <collision>
      <origin xyz="0. 0. 0.0175" rpy="0. 0. 0."/>
      <geometry>
        <sphere radius="0.017"/>
      </geometry>
    </collision>
    <collision>
      <origin xyz="0. 0. -0.0175" rpy="0. 0. 0."/>
      <geometry>
        <sphere radius="0.017"/>
      </geometry>
    </collision>
  </link>
  <link name="front_left_roller5_link">
    <inertial>
      <origin xyz="0. 0. 0." rpy="0. 0. 0."/>
      <mass value="0.0141372"/>
      <inertia ixx="0." ixy="0." ixz="0." iyy="0." iyz="0." izz="0."/>
    </inertial>
    <visual>
      <origin xyz="-0.00051 0. -0.035 " rpy="0. 0. 0."/>
      <geometry>
        <sphere radius="0.015"/>
      </geometry>
    </visual>
    <visual>
      <origin xyz="-0.00051 0. 0.035 " rpy="0. 0. 0."/>
      <geometry>
        <sphere radius="0.015"/>
      </geometry>
    </visual>
    <visual>
      <origin xyz="0. 0. 0." rpy="0. 0. 0."/>
      <geometry>
        <sphere radius="0.019"/>
      </geometry>
    </visual>
    <visual>
      <origin xyz="0. 0. 0.0175" rpy="0. 0. 0."/>
      <geometry>
        <sphere radius="0.017"/>
      </geometry>
    </visual>
    <visual>
      <origin xyz="0. 0. -0.0175" rpy="0. 0. 0."/>
      <geometry>
        <sphere radius="0.017"/>
      </geometry>
    </visual>
    <collision>
      <origin xyz="-0.00051 0. -0.035 " rpy="0. 0. 0."/>
      <geometry>
        <sphere radius="0.015"/>
      </geometry>
    </collision>
    <collision>
      <origin xyz="-0.00051 0. 0.035 " rpy="0. 0. 0."/>
      <geometry>
        <sphere radius="0.015"/>
      </geometry>
    </collision>
    <collision>
      <origin xyz="0. 0. 0." rpy="0. 0. 0."/>
      <geometry>
        <sphere radius="0.019"/>
      </geometry>
    </collision>
    <collision>
      <origin xyz="0. 0. 0.0175" rpy="0. 0. 0."/>
      <geometry>
        <sphere radius="0.017"/>
      </geometry>
    </collision>
    <collision>
      <origin xyz="0. 0. -0.0175" rpy="0. 0. 0."/>
      <geometry>
        <sphere radius="0.017"/>
      </geometry>
    </collision>
  </link>
  <link name="front_left_roller6_link">
    <inertial>
      <origin xyz="0. 0. 0." rpy="0. 0. 0."/>
      <mass value="0.0141372"/>
      <inertia ixx="0." ixy="0." ixz="0." iyy="0." iyz="0." izz="0."/>
    </inertial>
    <visual>
      <origin xyz="-0.00051 0. -0.035 " rpy="0. 0. 0."/>
      <geometry>
        <sphere radius="0.015"/>
      </geometry>
    </visual>
    <visual>
      <origin xyz="-0.00051 0. 0.035 " rpy="0. 0. 0."/>
      <geometry>
        <sphere radius="0.015"/>
      </geometry>
    </visual>
    <visual>
      <origin xyz="0. 0. 0." rpy="0. 0. 0."/>
      <geometry>
        <sphere radius="0.019"/>
      </geometry>
    </visual>
    <visual>
      <origin xyz="0. 0. 0.0175" rpy="0. 0. 0."/>
      <geometry>
        <sphere radius="0.017"/>
      </geometry>
    </visual>
    <visual>
      <origin xyz="0. 0. -0.0175" rpy="0. 0. 0."/>
      <geometry>
        <sphere radius="0.017"/>
      </geometry>
    </visual>
    <collision>
      <origin xyz="-0.00051 0. -0.035 " rpy="0. 0. 0."/>
      <geometry>
        <sphere radius="0.015"/>
      </geometry>
    </collision>
    <collision>
      <origin xyz="-0.00051 0. 0.035 " rpy="0. 0. 0."/>
      <geometry>
        <sphere radius="0.015"/>
      </geometry>
    </collision>
    <collision>
      <origin xyz="0. 0. 0." rpy="0. 0. 0."/>
      <geometry>
        <sphere radius="0.019"/>
      </geometry>
    </collision>
    <collision>
      <origin xyz="0. 0. 0.0175" rpy="0. 0. 0."/>
      <geometry>
        <sphere radius="0.017"/>
      </geometry>
    </collision>
    <collision>
      <origin xyz="0. 0. -0.0175" rpy="0. 0. 0."/>
      <geometry>
        <sphere radius="0.017"/>
      </geometry>
    </collision>
  </link>
  <link name="front_left_roller7_link">
    <inertial>
      <origin xyz="0. 0. 0." rpy="0. 0. 0."/>
      <mass value="0.0141372"/>
      <inertia ixx="0." ixy="0." ixz="0." iyy="0." iyz="0." izz="0."/>
    </inertial>
    <visual>
      <origin xyz="-0.00051 0. -0.035 " rpy="0. 0. 0."/>
      <geometry>
        <sphere radius="0.015"/>
      </geometry>
    </visual>
    <visual>
      <origin xyz="-0.00051 0. 0.035 " rpy="0. 0. 0."/>
      <geometry>
        <sphere radius="0.015"/>
      </geometry>
    </visual>
    <visual>
      <origin xyz="0. 0. 0." rpy="0. 0. 0."/>
      <geometry>
        <sphere radius="0.019"/>
      </geometry>
    </visual>
    <visual>
      <origin xyz="0. 0. 0.0175" rpy="0. 0. 0."/>
      <geometry>
        <sphere radius="0.017"/>
      </geometry>
    </visual>
    <visual>
      <origin xyz="0. 0. -0.0175" rpy="0. 0. 0."/>
      <geometry>
        <sphere radius="0.017"/>
      </geometry>
    </visual>
    <collision>
      <origin xyz="-0.00051 0. -0.035 " rpy="0. 0. 0."/>
      <geometry>
        <sphere radius="0.015"/>
      </geometry>
    </collision>
    <collision>
      <origin xyz="-0.00051 0. 0.035 " rpy="0. 0. 0."/>
      <geometry>
        <sphere radius="0.015"/>
      </geometry>
    </collision>
    <collision>
      <origin xyz="0. 0. 0." rpy="0. 0. 0."/>
      <geometry>
        <sphere radius="0.019"/>
      </geometry>
    </collision>
    <collision>
      <origin xyz="0. 0. 0.0175" rpy="0. 0. 0."/>
      <geometry>
        <sphere radius="0.017"/>
      </geometry>
    </collision>
    <collision>
      <origin xyz="0. 0. -0.0175" rpy="0. 0. 0."/>
      <geometry>
        <sphere radius="0.017"/>
      </geometry>
    </collision>
  </link>
  <link name="front_left_roller8_link">
    <inertial>
      <origin xyz="0. 0. 0." rpy="0. 0. 0."/>
      <mass value="0.0141372"/>
      <inertia ixx="0." ixy="0." ixz="0." iyy="0." iyz="0." izz="0."/>
    </inertial>
    <visual>
      <origin xyz="-0.00051 0. -0.035 " rpy="0. 0. 0."/>
      <geometry>
        <sphere radius="0.015"/>
      </geometry>
    </visual>
    <visual>
      <origin xyz="-0.00051 0. 0.035 " rpy="0. 0. 0."/>
      <geometry>
        <sphere radius="0.015"/>
      </geometry>
    </visual>
    <visual>
      <origin xyz="0. 0. 0." rpy="0. 0. 0."/>
      <geometry>
        <sphere radius="0.019"/>
      </geometry>
    </visual>
    <visual>
      <origin xyz="0. 0. 0.0175" rpy="0. 0. 0."/>
      <geometry>
        <sphere radius="0.017"/>
      </geometry>
    </visual>
    <visual>
      <origin xyz="0. 0. -0.0175" rpy="0. 0. 0."/>
      <geometry>
        <sphere radius="0.017"/>
      </geometry>
    </visual>
    <collision>
      <origin xyz="-0.00051 0. -0.035 " rpy="0. 0. 0."/>
      <geometry>
        <sphere radius="0.015"/>
      </geometry>
    </collision>
    <collision>
      <origin xyz="-0.00051 0. 0.035 " rpy="0. 0. 0."/>
      <geometry>
        <sphere radius="0.015"/>
      </geometry>
    </collision>
    <collision>
      <origin xyz="0. 0. 0." rpy="0. 0. 0."/>
      <geometry>
        <sphere radius="0.019"/>
      </geometry>
    </collision>
    <collision>
      <origin xyz="0. 0. 0.0175" rpy="0. 0. 0."/>
      <geometry>
        <sphere radius="0.017"/>
      </geometry>
    </collision>
    <collision>
      <origin xyz="0. 0. -0.0175" rpy="0. 0. 0."/>
      <geometry>
        <sphere radius="0.017"/>
      </geometry>
    </collision>
  </link>
  <link name="front_left_roller9_link">
    <inertial>
      <origin xyz="0. 0. 0." rpy="0. 0. 0."/>
      <mass value="0.0141372"/>
      <inertia ixx="0." ixy="0." ixz="0." iyy="0." iyz="0." izz="0."/>
    </inertial>
    <visual>
      <origin xyz="-0.00051 0. -0.035 " rpy="0. 0. 0."/>
      <geometry>
        <sphere radius="0.015"/>
      </geometry>
    </visual>
    <visual>
      <origin xyz="-0.00051 0. 0.035 " rpy="0. 0. 0."/>
      <geometry>
        <sphere radius="0.015"/>
      </geometry>
    </visual>
    <visual>
      <origin xyz="0. 0. 0." rpy="0. 0. 0."/>
      <geometry>
        <sphere radius="0.019"/>
      </geometry>
    </visual>
    <visual>
      <origin xyz="0. 0. 0.0175" rpy="0. 0. 0."/>
      <geometry>
        <sphere radius="0.017"/>
      </geometry>
    </visual>
    <visual>
      <origin xyz="0. 0. -0.0175" rpy="0. 0. 0."/>
      <geometry>
        <sphere radius="0.017"/>
      </geometry>
    </visual>
    <collision>
      <origin xyz="-0.00051 0. -0.035 " rpy="0. 0. 0."/>
      <geometry>
        <sphere radius="0.015"/>
      </geometry>
    </collision>
    <collision>
      <origin xyz="-0.00051 0. 0.035 " rpy="0. 0. 0."/>
      <geometry>
        <sphere radius="0.015"/>
      </geometry>
    </collision>
    <collision>
      <origin xyz="0. 0. 0." rpy="0. 0. 0."/>
      <geometry>
        <sphere radius="0.019"/>
      </geometry>
    </collision>
    <collision>
      <origin xyz="0. 0. 0.0175" rpy="0. 0. 0."/>
      <geometry>
        <sphere radius="0.017"/>
      </geometry>
    </collision>
    <collision>
      <origin xyz="0. 0. -0.0175" rpy="0. 0. 0."/>
      <geometry>
        <sphere radius="0.017"/>
      </geometry>
    </collision>
  </link>
  <link name="front_right_roller10_link">
    <inertial>
      <origin xyz="0. 0. 0." rpy="0. 0. 0."/>
      <mass value="0.0141372"/>
      <inertia ixx="0." ixy="0." ixz="0." iyy="0." iyz="0." izz="0."/>
    </inertial>
    <visual>
      <origin xyz="-0.00051 0. -0.035 " rpy="0. 0. 0."/>
      <geometry>
        <sphere radius="0.015"/>
      </geometry>
    </visual>
    <visual>
      <origin xyz="-0.00051 0. 0.035 " rpy="0. 0. 0."/>
      <geometry>
        <sphere radius="0.015"/>
      </geometry>
    </visual>
    <visual>
      <origin xyz="0. 0. 0." rpy="0. 0. 0."/>
      <geometry>
        <sphere radius="0.019"/>
      </geometry>
    </visual>
    <visual>
      <origin xyz="0. 0. 0.0175" rpy="0. 0. 0."/>
      <geometry>
        <sphere radius="0.017"/>
      </geometry>
    </visual>
    <visual>
      <origin xyz="0. 0. -0.0175" rpy="0. 0. 0."/>
      <geometry>
        <sphere radius="0.017"/>
      </geometry>
    </visual>
    <collision>
      <origin xyz="-0.00051 0. -0.035 " rpy="0. 0. 0."/>
      <geometry>
        <sphere radius="0.015"/>
      </geometry>
    </collision>
    <collision>
      <origin xyz="-0.00051 0. 0.035 " rpy="0. 0. 0."/>
      <geometry>
        <sphere radius="0.015"/>
      </geometry>
    </collision>
    <collision>
      <origin xyz="0. 0. 0." rpy="0. 0. 0."/>
      <geometry>
        <sphere radius="0.019"/>
      </geometry>
    </collision>
    <collision>
      <origin xyz="0. 0. 0.0175" rpy="0. 0. 0."/>
      <geometry>
        <sphere radius="0.017"/>
      </geometry>
    </collision>
    <collision>
      <origin xyz="0. 0. -0.0175" rpy="0. 0. 0."/>
      <geometry>
        <sphere radius="0.017"/>
      </geometry>
    </collision>
  </link>
  <link name="front_right_roller11_link">
    <inertial>
      <origin xyz="0. 0. 0." rpy="0. 0. 0."/>
      <mass value="0.0141372"/>
      <inertia ixx="0." ixy="0." ixz="0." iyy="0." iyz="0." izz="0."/>
    </inertial>
    <visual>
      <origin xyz="-0.00051 0. -0.035 " rpy="0. 0. 0."/>
      <geometry>
        <sphere radius="0.015"/>
      </geometry>
    </visual>
    <visual>
      <origin xyz="-0.00051 0. 0.035 " rpy="0. 0. 0."/>
      <geometry>
        <sphere radius="0.015"/>
      </geometry>
    </visual>
    <visual>
      <origin xyz="0. 0. 0." rpy="0. 0. 0."/>
      <geometry>
        <sphere radius="0.019"/>
      </geometry>
    </visual>
    <visual>
      <origin xyz="0. 0. 0.0175" rpy="0. 0. 0."/>
      <geometry>
        <sphere radius="0.017"/>
      </geometry>
    </visual>
    <visual>
      <origin xyz="0. 0. -0.0175" rpy="0. 0. 0."/>
      <geometry>
        <sphere radius="0.017"/>
      </geometry>
    </visual>
    <collision>
      <origin xyz="-0.00051 0. -0.035 " rpy="0. 0. 0."/>
      <geometry>
        <sphere radius="0.015"/>
      </geometry>
    </collision>
    <collision>
      <origin xyz="-0.00051 0. 0.035 " rpy="0. 0. 0."/>
      <geometry>
        <sphere radius="0.015"/>
      </geometry>
    </collision>
    <collision>
      <origin xyz="0. 0. 0." rpy="0. 0. 0."/>
      <geometry>
        <sphere radius="0.019"/>
      </geometry>
    </collision>
    <collision>
      <origin xyz="0. 0. 0.0175" rpy="0. 0. 0."/>
      <geometry>
        <sphere radius="0.017"/>
      </geometry>
    </collision>
    <collision>
      <origin xyz="0. 0. -0.0175" rpy="0. 0. 0."/>
      <geometry>
        <sphere radius="0.017"/>
      </geometry>
    </collision>
  </link>
  <link name="front_right_roller12_link">
    <inertial>
      <origin xyz="0. 0. 0." rpy="0. 0. 0."/>
      <mass value="0.0141372"/>
      <inertia ixx="0." ixy="0." ixz="0." iyy="0." iyz="0." izz="0."/>
    </inertial>
    <visual>
      <origin xyz="-0.00051 0. -0.035 " rpy="0. 0. 0."/>
      <geometry>
        <sphere radius="0.015"/>
      </geometry>
    </visual>
    <visual>
      <origin xyz="-0.00051 0. 0.035 " rpy="0. 0. 0."/>
      <geometry>
        <sphere radius="0.015"/>
      </geometry>
    </visual>
    <visual>
      <origin xyz="0. 0. 0." rpy="0. 0. 0."/>
      <geometry>
        <sphere radius="0.019"/>
      </geometry>
    </visual>
    <visual>
      <origin xyz="0. 0. 0.0175" rpy="0. 0. 0."/>
      <geometry>
        <sphere radius="0.017"/>
      </geometry>
    </visual>
    <visual>
      <origin xyz="0. 0. -0.0175" rpy="0. 0. 0."/>
      <geometry>
        <sphere radius="0.017"/>
      </geometry>
    </visual>
    <collision>
      <origin xyz="-0.00051 0. -0.035 " rpy="0. 0. 0."/>
      <geometry>
        <sphere radius="0.015"/>
      </geometry>
    </collision>
    <collision>
      <origin xyz="-0.00051 0. 0.035 " rpy="0. 0. 0."/>
      <geometry>
        <sphere radius="0.015"/>
      </geometry>
    </collision>
    <collision>
      <origin xyz="0. 0. 0." rpy="0. 0. 0."/>
      <geometry>
        <sphere radius="0.019"/>
      </geometry>
    </collision>
    <collision>
      <origin xyz="0. 0. 0.0175" rpy="0. 0. 0."/>
      <geometry>
        <sphere radius="0.017"/>
      </geometry>
    </collision>
    <collision>
      <origin xyz="0. 0. -0.0175" rpy="0. 0. 0."/>
      <geometry>
        <sphere radius="0.017"/>
      </geometry>
    </collision>
  </link>
  <link name="front_right_roller1_link">
    <inertial>
      <origin xyz="0. 0. 0." rpy="0. 0. 0."/>
      <mass value="0.0141372"/>
      <inertia ixx="0." ixy="0." ixz="0." iyy="0." iyz="0." izz="0."/>
    </inertial>
    <visual>
      <origin xyz="-0.00051 0. -0.035 " rpy="0. 0. 0."/>
      <geometry>
        <sphere radius="0.015"/>
      </geometry>
    </visual>
    <visual>
      <origin xyz="-0.00051 0. 0.035 " rpy="0. 0. 0."/>
      <geometry>
        <sphere radius="0.015"/>
      </geometry>
    </visual>
    <visual>
      <origin xyz="0. 0. 0." rpy="0. 0. 0."/>
      <geometry>
        <sphere radius="0.019"/>
      </geometry>
    </visual>
    <visual>
      <origin xyz="0. 0. 0.0175" rpy="0. 0. 0."/>
      <geometry>
        <sphere radius="0.017"/>
      </geometry>
    </visual>
    <visual>
      <origin xyz="0. 0. -0.0175" rpy="0. 0. 0."/>
      <geometry>
        <sphere radius="0.017"/>
      </geometry>
    </visual>
    <collision>
      <origin xyz="-0.00051 0. -0.035 " rpy="0. 0. 0."/>
      <geometry>
        <sphere radius="0.015"/>
      </geometry>
    </collision>
    <collision>
      <origin xyz="-0.00051 0. 0.035 " rpy="0. 0. 0."/>
      <geometry>
        <sphere radius="0.015"/>
      </geometry>
    </collision>
    <collision>
      <origin xyz="0. 0. 0." rpy="0. 0. 0."/>
      <geometry>
        <sphere radius="0.019"/>
      </geometry>
    </collision>
    <collision>
      <origin xyz="0. 0. 0.0175" rpy="0. 0. 0."/>
      <geometry>
        <sphere radius="0.017"/>
      </geometry>
    </collision>
    <collision>
      <origin xyz="0. 0. -0.0175" rpy="0. 0. 0."/>
      <geometry>
        <sphere radius="0.017"/>
      </geometry>
    </collision>
  </link>
  <link name="front_right_roller2_link">
    <inertial>
      <origin xyz="0. 0. 0." rpy="0. 0. 0."/>
      <mass value="0.0141372"/>
      <inertia ixx="0." ixy="0." ixz="0." iyy="0." iyz="0." izz="0."/>
    </inertial>
    <visual>
      <origin xyz="-0.00051 0. -0.035 " rpy="0. 0. 0."/>
      <geometry>
        <sphere radius="0.015"/>
      </geometry>
    </visual>
    <visual>
      <origin xyz="-0.00051 0. 0.035 " rpy="0. 0. 0."/>
      <geometry>
        <sphere radius="0.015"/>
      </geometry>
    </visual>
    <visual>
      <origin xyz="0. 0. 0." rpy="0. 0. 0."/>
      <geometry>
        <sphere radius="0.019"/>
      </geometry>
    </visual>
    <visual>
      <origin xyz="0. 0. 0.0175" rpy="0. 0. 0."/>
      <geometry>
        <sphere radius="0.017"/>
      </geometry>
    </visual>
    <visual>
      <origin xyz="0. 0. -0.0175" rpy="0. 0. 0."/>
      <geometry>
        <sphere radius="0.017"/>
      </geometry>
    </visual>
    <collision>
      <origin xyz="-0.00051 0. -0.035 " rpy="0. 0. 0."/>
      <geometry>
        <sphere radius="0.015"/>
      </geometry>
    </collision>
    <collision>
      <origin xyz="-0.00051 0. 0.035 " rpy="0. 0. 0."/>
      <geometry>
        <sphere radius="0.015"/>
      </geometry>
    </collision>
    <collision>
      <origin xyz="0. 0. 0." rpy="0. 0. 0."/>
      <geometry>
        <sphere radius="0.019"/>
      </geometry>
    </collision>
    <collision>
      <origin xyz="0. 0. 0.0175" rpy="0. 0. 0."/>
      <geometry>
        <sphere radius="0.017"/>
      </geometry>
    </collision>
    <collision>
      <origin xyz="0. 0. -0.0175" rpy="0. 0. 0."/>
      <geometry>
        <sphere radius="0.017"/>
      </geometry>
    </collision>
  </link>
  <link name="front_right_roller3_link">
    <inertial>
      <origin xyz="0. 0. 0." rpy="0. 0. 0."/>
      <mass value="0.0141372"/>
      <inertia ixx="0." ixy="0." ixz="0." iyy="0." iyz="0." izz="0."/>
    </inertial>
    <visual>
      <origin xyz="-0.00051 0. -0.035 " rpy="0. 0. 0."/>
      <geometry>
        <sphere radius="0.015"/>
      </geometry>
    </visual>
    <visual>
      <origin xyz="-0.00051 0. 0.035 " rpy="0. 0. 0."/>
      <geometry>
        <sphere radius="0.015"/>
      </geometry>
    </visual>
    <visual>
      <origin xyz="0. 0. 0." rpy="0. 0. 0."/>
      <geometry>
        <sphere radius="0.019"/>
      </geometry>
    </visual>
    <visual>
      <origin xyz="0. 0. 0.0175" rpy="0. 0. 0."/>
      <geometry>
        <sphere radius="0.017"/>
      </geometry>
    </visual>
    <visual>
      <origin xyz="0. 0. -0.0175" rpy="0. 0. 0."/>
      <geometry>
        <sphere radius="0.017"/>
      </geometry>
    </visual>
    <collision>
      <origin xyz="-0.00051 0. -0.035 " rpy="0. 0. 0."/>
      <geometry>
        <sphere radius="0.015"/>
      </geometry>
    </collision>
    <collision>
      <origin xyz="-0.00051 0. 0.035 " rpy="0. 0. 0."/>
      <geometry>
        <sphere radius="0.015"/>
      </geometry>
    </collision>
    <collision>
      <origin xyz="0. 0. 0." rpy="0. 0. 0."/>
      <geometry>
        <sphere radius="0.019"/>
      </geometry>
    </collision>
    <collision>
      <origin xyz="0. 0. 0.0175" rpy="0. 0. 0."/>
      <geometry>
        <sphere radius="0.017"/>
      </geometry>
    </collision>
    <collision>
      <origin xyz="0. 0. -0.0175" rpy="0. 0. 0."/>
      <geometry>
        <sphere radius="0.017"/>
      </geometry>
    </collision>
  </link>
  <link name="front_right_roller4_link">
    <inertial>
      <origin xyz="0. 0. 0." rpy="0. 0. 0."/>
      <mass value="0.0141372"/>
      <inertia ixx="0." ixy="0." ixz="0." iyy="0." iyz="0." izz="0."/>
    </inertial>
    <visual>
      <origin xyz="-0.00051 0. -0.035 " rpy="0. 0. 0."/>
      <geometry>
        <sphere radius="0.015"/>
      </geometry>
    </visual>
    <visual>
      <origin xyz="-0.00051 0. 0.035 " rpy="0. 0. 0."/>
      <geometry>
        <sphere radius="0.015"/>
      </geometry>
    </visual>
    <visual>
      <origin xyz="0. 0. 0." rpy="0. 0. 0."/>
      <geometry>
        <sphere radius="0.019"/>
      </geometry>
    </visual>
    <visual>
      <origin xyz="0. 0. 0.0175" rpy="0. 0. 0."/>
      <geometry>
        <sphere radius="0.017"/>
      </geometry>
    </visual>
    <visual>
      <origin xyz="0. 0. -0.0175" rpy="0. 0. 0."/>
      <geometry>
        <sphere radius="0.017"/>
      </geometry>
    </visual>
    <collision>
      <origin xyz="-0.00051 0. -0.035 " rpy="0. 0. 0."/>
      <geometry>
        <sphere radius="0.015"/>
      </geometry>
    </collision>
    <collision>
      <origin xyz="-0.00051 0. 0.035 " rpy="0. 0. 0."/>
      <geometry>
        <sphere radius="0.015"/>
      </geometry>
    </collision>
    <collision>
      <origin xyz="0. 0. 0." rpy="0. 0. 0."/>
      <geometry>
        <sphere radius="0.019"/>
      </geometry>
    </collision>
    <collision>
      <origin xyz="0. 0. 0.0175" rpy="0. 0. 0."/>
      <geometry>
        <sphere radius="0.017"/>
      </geometry>
    </collision>
    <collision>
      <origin xyz="0. 0. -0.0175" rpy="0. 0. 0."/>
      <geometry>
        <sphere radius="0.017"/>
      </geometry>
    </collision>
  </link>
  <link name="front_right_roller5_link">
    <inertial>
      <origin xyz="0. 0. 0." rpy="0. 0. 0."/>
      <mass value="0.0141372"/>
      <inertia ixx="0." ixy="0." ixz="0." iyy="0." iyz="0." izz="0."/>
    </inertial>
    <visual>
      <origin xyz="-0.00051 0. -0.035 " rpy="0. 0. 0."/>
      <geometry>
        <sphere radius="0.015"/>
      </geometry>
    </visual>
    <visual>
      <origin xyz="-0.00051 0. 0.035 " rpy="0. 0. 0."/>
      <geometry>
        <sphere radius="0.015"/>
      </geometry>
    </visual>
    <visual>
      <origin xyz="0. 0. 0." rpy="0. 0. 0."/>
      <geometry>
        <sphere radius="0.019"/>
      </geometry>
    </visual>
    <visual>
      <origin xyz="0. 0. 0.0175" rpy="0. 0. 0."/>
      <geometry>
        <sphere radius="0.017"/>
      </geometry>
    </visual>
    <visual>
      <origin xyz="0. 0. -0.0175" rpy="0. 0. 0."/>
      <geometry>
        <sphere radius="0.017"/>
      </geometry>
    </visual>
    <collision>
      <origin xyz="-0.00051 0. -0.035 " rpy="0. 0. 0."/>
      <geometry>
        <sphere radius="0.015"/>
      </geometry>
    </collision>
    <collision>
      <origin xyz="-0.00051 0. 0.035 " rpy="0. 0. 0."/>
      <geometry>
        <sphere radius="0.015"/>
      </geometry>
    </collision>
    <collision>
      <origin xyz="0. 0. 0." rpy="0. 0. 0."/>
      <geometry>
        <sphere radius="0.019"/>
      </geometry>
    </collision>
    <collision>
      <origin xyz="0. 0. 0.0175" rpy="0. 0. 0."/>
      <geometry>
        <sphere radius="0.017"/>
      </geometry>
    </collision>
    <collision>
      <origin xyz="0. 0. -0.0175" rpy="0. 0. 0."/>
      <geometry>
        <sphere radius="0.017"/>
      </geometry>
    </collision>
  </link>
  <link name="front_right_roller6_link">
    <inertial>
      <origin xyz="0. 0. 0." rpy="0. 0. 0."/>
      <mass value="0.0141372"/>
      <inertia ixx="0." ixy="0." ixz="0." iyy="0." iyz="0." izz="0."/>
    </inertial>
    <visual>
      <origin xyz="-0.00051 0. -0.035 " rpy="0. 0. 0."/>
      <geometry>
        <sphere radius="0.015"/>
      </geometry>
    </visual>
    <visual>
      <origin xyz="-0.00051 0. 0.035 " rpy="0. 0. 0."/>
      <geometry>
        <sphere radius="0.015"/>
      </geometry>
    </visual>
    <visual>
      <origin xyz="0. 0. 0." rpy="0. 0. 0."/>
      <geometry>
        <sphere radius="0.019"/>
      </geometry>
    </visual>
    <visual>
      <origin xyz="0. 0. 0.0175" rpy="0. 0. 0."/>
      <geometry>
        <sphere radius="0.017"/>
      </geometry>
    </visual>
    <visual>
      <origin xyz="0. 0. -0.0175" rpy="0. 0. 0."/>
      <geometry>
        <sphere radius="0.017"/>
      </geometry>
    </visual>
    <collision>
      <origin xyz="-0.00051 0. -0.035 " rpy="0. 0. 0."/>
      <geometry>
        <sphere radius="0.015"/>
      </geometry>
    </collision>
    <collision>
      <origin xyz="-0.00051 0. 0.035 " rpy="0. 0. 0."/>
      <geometry>
        <sphere radius="0.015"/>
      </geometry>
    </collision>
    <collision>
      <origin xyz="0. 0. 0." rpy="0. 0. 0."/>
      <geometry>
        <sphere radius="0.019"/>
      </geometry>
    </collision>
    <collision>
      <origin xyz="0. 0. 0.0175" rpy="0. 0. 0."/>
      <geometry>
        <sphere radius="0.017"/>
      </geometry>
    </collision>
    <collision>
      <origin xyz="0. 0. -0.0175" rpy="0. 0. 0."/>
      <geometry>
        <sphere radius="0.017"/>
      </geometry>
    </collision>
  </link>
  <link name="front_right_roller7_link">
    <inertial>
      <origin xyz="0. 0. 0." rpy="0. 0. 0."/>
      <mass value="0.0141372"/>
      <inertia ixx="0." ixy="0." ixz="0." iyy="0." iyz="0." izz="0."/>
    </inertial>
    <visual>
      <origin xyz="-0.00051 0. -0.035 " rpy="0. 0. 0."/>
      <geometry>
        <sphere radius="0.015"/>
      </geometry>
    </visual>
    <visual>
      <origin xyz="-0.00051 0. 0.035 " rpy="0. 0. 0."/>
      <geometry>
        <sphere radius="0.015"/>
      </geometry>
    </visual>
    <visual>
      <origin xyz="0. 0. 0." rpy="0. 0. 0."/>
      <geometry>
        <sphere radius="0.019"/>
      </geometry>
    </visual>
    <visual>
      <origin xyz="0. 0. 0.0175" rpy="0. 0. 0."/>
      <geometry>
        <sphere radius="0.017"/>
      </geometry>
    </visual>
    <visual>
      <origin xyz="0. 0. -0.0175" rpy="0. 0. 0."/>
      <geometry>
        <sphere radius="0.017"/>
      </geometry>
    </visual>
    <collision>
      <origin xyz="-0.00051 0. -0.035 " rpy="0. 0. 0."/>
      <geometry>
        <sphere radius="0.015"/>
      </geometry>
    </collision>
    <collision>
      <origin xyz="-0.00051 0. 0.035 " rpy="0. 0. 0."/>
      <geometry>
        <sphere radius="0.015"/>
      </geometry>
    </collision>
    <collision>
      <origin xyz="0. 0. 0." rpy="0. 0. 0."/>
      <geometry>
        <sphere radius="0.019"/>
      </geometry>
    </collision>
    <collision>
      <origin xyz="0. 0. 0.0175" rpy="0. 0. 0."/>
      <geometry>
        <sphere radius="0.017"/>
      </geometry>
    </collision>
    <collision>
      <origin xyz="0. 0. -0.0175" rpy="0. 0. 0."/>
      <geometry>
        <sphere radius="0.017"/>
      </geometry>
    </collision>
  </link>
  <link name="front_right_roller8_link">
    <inertial>
      <origin xyz="0. 0. 0." rpy="0. 0. 0."/>
      <mass value="0.0141372"/>
      <inertia ixx="0." ixy="0." ixz="0." iyy="0." iyz="0." izz="0."/>
    </inertial>
    <visual>
      <origin xyz="-0.00051 0. -0.035 " rpy="0. 0. 0."/>
      <geometry>
        <sphere radius="0.015"/>
      </geometry>
    </visual>
    <visual>
      <origin xyz="-0.00051 0. 0.035 " rpy="0. 0. 0."/>
      <geometry>
        <sphere radius="0.015"/>
      </geometry>
    </visual>
    <visual>
      <origin xyz="0. 0. 0." rpy="0. 0. 0."/>
      <geometry>
        <sphere radius="0.019"/>
      </geometry>
    </visual>
    <visual>
      <origin xyz="0. 0. 0.0175" rpy="0. 0. 0."/>
      <geometry>
        <sphere radius="0.017"/>
      </geometry>
    </visual>
    <visual>
      <origin xyz="0. 0. -0.0175" rpy="0. 0. 0."/>
      <geometry>
        <sphere radius="0.017"/>
      </geometry>
    </visual>
    <collision>
      <origin xyz="-0.00051 0. -0.035 " rpy="0. 0. 0."/>
      <geometry>
        <sphere radius="0.015"/>
      </geometry>
    </collision>
    <collision>
      <origin xyz="-0.00051 0. 0.035 " rpy="0. 0. 0."/>
      <geometry>
        <sphere radius="0.015"/>
      </geometry>
    </collision>
    <collision>
      <origin xyz="0. 0. 0." rpy="0. 0. 0."/>
      <geometry>
        <sphere radius="0.019"/>
      </geometry>
    </collision>
    <collision>
      <origin xyz="0. 0. 0.0175" rpy="0. 0. 0."/>
      <geometry>
        <sphere radius="0.017"/>
      </geometry>
    </collision>
    <collision>
      <origin xyz="0. 0. -0.0175" rpy="0. 0. 0."/>
      <geometry>
        <sphere radius="0.017"/>
      </geometry>
    </collision>
  </link>
  <link name="front_right_roller9_link">
    <inertial>
      <origin xyz="0. 0. 0." rpy="0. 0. 0."/>
      <mass value="0.0141372"/>
      <inertia ixx="0." ixy="0." ixz="0." iyy="0." iyz="0." izz="0."/>
    </inertial>
    <visual>
      <origin xyz="-0.00051 0. -0.035 " rpy="0. 0. 0."/>
      <geometry>
        <sphere radius="0.015"/>
      </geometry>
    </visual>
    <visual>
      <origin xyz="-0.00051 0. 0.035 " rpy="0. 0. 0."/>
      <geometry>
        <sphere radius="0.015"/>
      </geometry>
    </visual>
    <visual>
      <origin xyz="0. 0. 0." rpy="0. 0. 0."/>
      <geometry>
        <sphere radius="0.019"/>
      </geometry>
    </visual>
    <visual>
      <origin xyz="0. 0. 0.0175" rpy="0. 0. 0."/>
      <geometry>
        <sphere radius="0.017"/>
      </geometry>
    </visual>
    <visual>
      <origin xyz="0. 0. -0.0175" rpy="0. 0. 0."/>
      <geometry>
        <sphere radius="0.017"/>
      </geometry>
    </visual>
    <collision>
      <origin xyz="-0.00051 0. -0.035 " rpy="0. 0. 0."/>
      <geometry>
        <sphere radius="0.015"/>
      </geometry>
    </collision>
    <collision>
      <origin xyz="-0.00051 0. 0.035 " rpy="0. 0. 0."/>
      <geometry>
        <sphere radius="0.015"/>
      </geometry>
    </collision>
    <collision>
      <origin xyz="0. 0. 0." rpy="0. 0. 0."/>
      <geometry>
        <sphere radius="0.019"/>
      </geometry>
    </collision>
    <collision>
      <origin xyz="0. 0. 0.0175" rpy="0. 0. 0."/>
      <geometry>
        <sphere radius="0.017"/>
      </geometry>
    </collision>
    <collision>
      <origin xyz="0. 0. -0.0175" rpy="0. 0. 0."/>
      <geometry>
        <sphere radius="0.017"/>
      </geometry>
    </collision>
  </link>
  <link name="panda_leftfinger">
    <inertial>
      <origin xyz="0. 0. 0." rpy="0. 0. 0."/>
      <mass value="0.0140552"/>
      <inertia ixx="0." ixy="0." ixz="0." iyy="0." iyz="0." izz="0."/>
    </inertial>
    <visual>
      <origin xyz="0. 0. 0." rpy="0. 0. -1.5707964"/>
      <geometry>
        <mesh filename="package://robot_description/meshes/panda_leftfinger_geometry_ID27.obj" scale="1. 1. 1."/>
      </geometry>
    </visual>
    <visual>
      <origin xyz="0. 0. 0." rpy="0. 0. -1.5707964"/>
      <geometry>
        <mesh filename="package://robot_description/meshes/panda_leftfinger_geometry_ID27fa3.obj" scale="1. 1. 1."/>
      </geometry>
    </visual>
    <visual>
      <origin xyz="0. 0. 0." rpy="0. 0. -1.5707964"/>
      <geometry>
        <mesh filename="package://robot_description/meshes/panda_leftfinger_geometry_ID27SVM.obj" scale="1. 1. 1."/>
      </geometry>
    </visual>
    <collision>
      <origin xyz="0. 0. 0." rpy="0. 0. -1.5707964"/>
      <geometry>
        <mesh filename="package://robot_description/meshes/panda_leftfinger_geometry_ID27.obj" scale="1. 1. 1."/>
      </geometry>
    </collision>
    <collision>
      <origin xyz="0. 0. 0." rpy="0. 0. -1.5707964"/>
      <geometry>
        <mesh filename="package://robot_description/meshes/panda_leftfinger_geometry_ID27SVM.obj" scale="1. 1. 1."/>
      </geometry>
    </collision>
  </link>
  <link name="panda_link0">
    <inertial>
      <origin xyz="0. 0. 0." rpy="0. 0. 0."/>
      <mass value="2.8142028"/>
      <inertia ixx="0." ixy="0." ixz="0." iyy="0." iyz="0." izz="0."/>
    </inertial>
    <visual>
      <origin xyz="-0. -0. -0.0000001" rpy="0. 0. -1.5692037"/>
      <geometry>
        <mesh filename="package://robot_description/meshes/panda_link0_geometry_ID3_000.obj" scale="1. 1. 1."/>
      </geometry>
    </visual>
    <visual>
      <origin xyz="-0. -0. -0.0000001" rpy="0. 0. -1.5692037"/>
      <geometry>
        <mesh filename="package://robot_description/meshes/ID3_000frA.obj" scale="1. 1. 1."/>
      </geometry>
    </visual>
    <visual>
      <origin xyz="-0. -0. -0.0000001" rpy="0. 0. -1.5692037"/>
      <geometry>
        <mesh filename="package://robot_description/meshes/ID3_000jEI.obj" scale="1. 1. 1."/>
      </geometry>
    </visual>
    <visual>
      <origin xyz="-0. -0. -0.0000001" rpy="0. 0. -1.5692037"/>
      <geometry>
        <mesh filename="package://robot_description/meshes/ID3_000m4u.obj" scale="1. 1. 1."/>
      </geometry>
    </visual>
    <visual>
      <origin xyz="-0. -0. -0.0000001" rpy="0. 0. -1.5692037"/>
      <geometry>
        <mesh filename="package://robot_description/meshes/ID3_000pR3.obj" scale="1. 1. 1."/>
      </geometry>
    </visual>
    <collision>
      <origin xyz="-0. -0. -0.0000001" rpy="0. 0. -1.5692037"/>
      <geometry>
        <mesh filename="package://robot_description/meshes/ID3_000frA.obj" scale="1. 1. 1."/>
      </geometry>
    </collision>
  </link>
  <link name="panda_link1">
    <inertial>
      <origin xyz="0. 0. 0." rpy="0. 0. 0."/>
      <mass value="2.3599997"/>
      <inertia ixx="0." ixy="0." ixz="0." iyy="0." iyz="0." izz="0."/>
    </inertial>
    <visual>
      <origin xyz="-0.192 -0. -0. " rpy="0. 1.5707961 0. "/>
      <geometry>
        <mesh filename="package://robot_description/meshes/panda_link1_geometry_ID3_000.obj" scale="1. 1. 1."/>
      </geometry>
    </visual>
    <collision>
      <origin xyz="-0.192 -0. -0. " rpy="0. 1.5707961 0. "/>
      <geometry>
        <mesh filename="package://robot_description/meshes/panda_link1_geometry_ID3_000.obj" scale="1. 1. 1."/>
      </geometry>
    </collision>
  </link>
  <link name="panda_link2">
    <inertial>
      <origin xyz="0. 0. 0." rpy="0. 0. 0."/>
      <mass value="2.3795187"/>
      <inertia ixx="0." ixy="0." ixz="0." iyy="0." iyz="0." izz="0."/>
    </inertial>
    <visual>
      <origin xyz="-0. 0. 0." rpy="-0.0000003 1.5707964 0. "/>
      <geometry>
        <mesh filename="package://robot_description/meshes/panda_link2_geometry_ID3_000.obj" scale="1. 1. 1."/>
      </geometry>
    </visual>
    <collision>
      <origin xyz="-0. 0. 0." rpy="-0.0000003 1.5707964 0. "/>
      <geometry>
        <mesh filename="package://robot_description/meshes/panda_link2_geometry_ID3_000.obj" scale="1. 1. 1."/>
      </geometry>
    </collision>
  </link>
  <link name="panda_link3">
    <inertial>
      <origin xyz="0. 0. 0." rpy="0. 0. 0."/>
      <mass value="2.6498823"/>
      <inertia ixx="0." ixy="0." ixz="0." iyy="0." iyz="0." izz="0."/>
    </inertial>
    <visual>
      <origin xyz="-0.121 0. 0. " rpy="0. 1.5707964 0. "/>
      <geometry>
        <mesh filename="package://robot_description/meshes/ID17_001.obj" scale="1. 1. 1."/>
      </geometry>
    </visual>
    <visual>
      <origin xyz="-0.121 0. 0. " rpy="0. 1.5707964 0. "/>
      <geometry>
        <mesh filename="package://robot_description/meshes/ID17_001frA.obj" scale="1. 1. 1."/>
      </geometry>
    </visual>
    <collision>
      <origin xyz="-0.121 0. 0. " rpy="0. 1.5707964 0. "/>
      <geometry>
        <mesh filename="package://robot_description/meshes/ID17_001.obj" scale="1. 1. 1."/>
      </geometry>
    </collision>
  </link>
  <link name="panda_link4">
    <inertial>
      <origin xyz="0. 0. 0." rpy="0. 0. 0."/>
      <mass value="2.6948018"/>
      <inertia ixx="0." ixy="0." ixz="0." iyy="0." iyz="0." izz="0."/>
    </inertial>
    <visual>
      <origin xyz="0. 0. 0." rpy="-3.1415927 0.0002617 -3.1415927"/>
      <geometry>
        <mesh filename="package://robot_description/meshes/ID25_000.obj" scale="1. 1. 1."/>
      </geometry>
    </visual>
    <visual>
      <origin xyz="0. 0. 0." rpy="-3.1415927 0. -3.1415927"/>
      <geometry>
        <mesh filename="package://robot_description/meshes/ID25_000frA.obj" scale="1. 1. 1."/>
      </geometry>
    </visual>
    <collision>
      <origin xyz="0. 0. 0." rpy="-3.1415927 0. -3.1415927"/>
      <geometry>
        <mesh filename="package://robot_description/meshes/ID25_000frA.obj" scale="1. 1. 1."/>
      </geometry>
    </collision>
  </link>
  <link name="panda_link5">
    <inertial>
      <origin xyz="0. 0. 0." rpy="0. 0. 0."/>
      <mass value="2.9812818"/>
      <inertia ixx="0." ixy="0." ixz="0." iyy="0." iyz="0." izz="0."/>
    </inertial>
    <visual>
      <origin xyz="-0.259 0. 0. " rpy="0. 1.5707963 0. "/>
      <geometry>
        <mesh filename="package://robot_description/meshes/ID11_000.obj" scale="1. 1. 1."/>
      </geometry>
    </visual>
    <visual>
      <origin xyz="-0.259 0. 0. " rpy="0. 1.5707963 0. "/>
      <geometry>
        <mesh filename="package://robot_description/meshes/ID11_000frA.obj" scale="1. 1. 1."/>
      </geometry>
    </visual>
    <collision>
      <origin xyz="-0.259 0. 0. " rpy="0. 1.5707963 0. "/>
      <geometry>
        <mesh filename="package://robot_description/meshes/ID11_000.obj" scale="1. 1. 1."/>
      </geometry>
    </collision>
  </link>
  <link name="panda_link6">
    <inertial>
      <origin xyz="0. 0. 0." rpy="0. 0. 0."/>
      <mass value="1.1285807"/>
      <inertia ixx="0." ixy="0." ixz="0." iyy="0." iyz="0." izz="0."/>
    </inertial>
    <visual>
      <origin xyz="-0.015 0. 0. " rpy="0. 1.5707963 0. "/>
      <geometry>
        <mesh filename="package://robot_description/meshes/ID389_001.obj" scale="1. 1. 1."/>
      </geometry>
    </visual>
    <visual>
      <origin xyz="-0.015 0. 0. " rpy="0. 1.5707963 0. "/>
      <geometry>
        <mesh filename="package://robot_description/meshes/ID389_001frA.obj" scale="1. 1. 1."/>
      </geometry>
    </visual>
    <visual>
      <origin xyz="-0.015 0. 0. " rpy="0. 1.5707963 0. "/>
      <geometry>
        <mesh filename="package://robot_description/meshes/ID389_001jEI.obj" scale="1. 1. 1."/>
      </geometry>
    </visual>
    <visual>
      <origin xyz="-0.015 0. 0. " rpy="0. 1.5707963 0. "/>
      <geometry>
        <mesh filename="package://robot_description/meshes/ID389_001m4u.obj" scale="1. 1. 1."/>
      </geometry>
    </visual>
    <visual>
      <origin xyz="-0.015 0. 0. " rpy="0. 1.5707963 0. "/>
      <geometry>
        <mesh filename="package://robot_description/meshes/ID389_001pR3.obj" scale="1. 1. 1."/>
      </geometry>
    </visual>
    <visual>
      <origin xyz="-0.015 0. 0. " rpy="0. 1.5707963 0. "/>
      <geometry>
        <mesh filename="package://robot_description/meshes/ID389_001snf.obj" scale="1. 1. 1."/>
      </geometry>
    </visual>
    <visual>
      <origin xyz="-0.015 0. 0. " rpy="0. 1.5707963 0. "/>
      <geometry>
        <mesh filename="package://robot_description/meshes/ID389_001wdn.obj" scale="1. 1. 1."/>
      </geometry>
    </visual>
    <visual>
      <origin xyz="-0.015 0. 0. " rpy="0. 1.5707963 0. "/>
      <geometry>
        <mesh filename="package://robot_description/meshes/ID389_001z0P.obj" scale="1. 1. 1."/>
      </geometry>
    </visual>
    <visual>
      <origin xyz="-0.015 0. 0. " rpy="0. 1.5707963 0. "/>
      <geometry>
        <mesh filename="package://robot_description/meshes/ID389_0012M1.obj" scale="1. 1. 1."/>
      </geometry>
    </visual>
    <collision>
      <origin xyz="-0.015 0. 0. " rpy="0. 1.5707963 0. "/>
      <geometry>
        <mesh filename="package://robot_description/meshes/ID389_001frA.obj" scale="1. 1. 1."/>
      </geometry>
    </collision>
  </link>
  <link name="panda_link7">
    <inertial>
      <origin xyz="0. 0. 0." rpy="0. 0. 0."/>
      <mass value="0.4052913"/>
      <inertia ixx="0." ixy="0." ixz="0." iyy="0." iyz="0." izz="0."/>
    </inertial>
    <visual>
      <origin xyz="0.0519999 0. -0.0000001" rpy="-1.570796 0.7853981 -1.5707958"/>
      <geometry>
        <mesh filename="package://robot_description/meshes/ID1683_001.obj" scale="1. 1. 1."/>
      </geometry>
    </visual>
    <visual>
      <origin xyz="0.0519999 0. -0.0000001" rpy="-1.570796 0.7853981 -1.5707958"/>
      <geometry>
        <mesh filename="package://robot_description/meshes/ID1683_001frA.obj" scale="1. 1. 1."/>
      </geometry>
    </visual>
    <visual>
      <origin xyz="0.0519999 0. -0.0000001" rpy="-1.570796 0.7853981 -1.5707958"/>
      <geometry>
        <mesh filename="package://robot_description/meshes/ID1683_001jEI.obj" scale="1. 1. 1."/>
      </geometry>
    </visual>
    <collision>
      <origin xyz="0.0519999 0. -0.0000001" rpy="-1.570796 0.7853981 -1.5707958"/>
      <geometry>
        <mesh filename="package://robot_description/meshes/ID1683_001.obj" scale="1. 1. 1."/>
      </geometry>
    </collision>
    <collision>
      <origin xyz="0.0519999 0. -0.0000001" rpy="-1.570796 0.7853981 -1.5707958"/>
      <geometry>
        <mesh filename="package://robot_description/meshes/ID1683_001frA.obj" scale="1. 1. 1."/>
      </geometry>
    </collision>
  </link>
  <link name="panda_link8">
    <inertial>
      <origin xyz="0. 0. 0." rpy="0. 0. 0."/>
      <mass value="0.1"/>
      <inertia ixx="0." ixy="0." ixz="0." iyy="0." iyz="0." izz="0."/>
    </inertial>
  </link>
  <link name="panda_rightfinger">
    <inertial>
      <origin xyz="0. 0. 0." rpy="0. 0. 0."/>
      <mass value="0.0140552"/>
      <inertia ixx="0." ixy="0." ixz="0." iyy="0." iyz="0." izz="0."/>
    </inertial>
    <visual>
      <origin xyz="0. 0. 0." rpy="0. 0. -1.5707964"/>
      <geometry>
        <mesh filename="package://robot_description/meshes/panda_rightfinger_geometry_ID27.obj" scale="1. 1. 1."/>
      </geometry>
    </visual>
    <visual>
      <origin xyz="0. 0. 0." rpy="0. 0. -1.5707964"/>
      <geometry>
        <mesh filename="package://robot_description/meshes/panda_rightfinger_geometry_ID27fa3.obj" scale="1. 1. 1."/>
      </geometry>
    </visual>
    <visual>
      <origin xyz="0. 0. 0." rpy="0. 0. -1.5707964"/>
      <geometry>
        <mesh filename="package://robot_description/meshes/panda_rightfinger_geometry_ID27SVM.obj" scale="1. 1. 1."/>
      </geometry>
    </visual>
    <collision>
      <origin xyz="0. 0. 0." rpy="0. 0. -1.5707964"/>
      <geometry>
        <mesh filename="package://robot_description/meshes/panda_rightfinger_geometry_ID27.obj" scale="1. 1. 1."/>
      </geometry>
    </collision>
    <collision>
      <origin xyz="0. 0. 0." rpy="0. 0. -1.5707964"/>
      <geometry>
        <mesh filename="package://robot_description/meshes/panda_rightfinger_geometry_ID27SVM.obj" scale="1. 1. 1."/>
      </geometry>
    </collision>
  </link>
  <link name="base_footprint">
    <visual>
      <origin xyz="0.0105128 -0.0236122 -0.0019743" rpy="0.0003379 -0.0016197 0.011564 "/>
      <geometry>
        <box size="0.001 0.001 0.001"/>
      </geometry>
    </visual>
    <visual>
      <origin xyz="0. 0. 0." rpy="0. 0. 0."/>
      <geometry>
        <mesh filename="package://robot_description/meshes/CollisionMesh.obj" scale="1. 1. 1."/>
      </geometry>
    </visual>
  </link>
  <link name="rbkairos_os1_mesh">
    <visual>
      <origin xyz="0. 0. 0." rpy="1.5707964 0. 1.5707964"/>
      <geometry>
        <mesh filename="package://robot_description/meshes/rbkairos_os1_mesh_os1_mesh.obj" scale="0.1 0.1 0.1"/>
      </geometry>
    </visual>
  </link>
  <link name="robot_base_chapa">
    <inertial>
      <origin xyz="0. 0. 0." rpy="0. 0. 0."/>
      <mass value="0.000001"/>
      <inertia ixx="0." ixy="0." ixz="0." iyy="0." iyz="0." izz="0."/>
    </inertial>
    <visual>
      <origin xyz="0. 0. 0." rpy="0. 0. 0."/>
      <geometry>
        <mesh filename="package://robot_description/meshes/robot_base_chapa_visuals.obj" scale="1. 1. 1."/>
      </geometry>
    </visual>
  </link>
  <link name="robot_base_docking_contact">
    <inertial>
      <origin xyz="0. 0. 0." rpy="0. 0. 0."/>
      <mass value="0.000001"/>
      <inertia ixx="0." ixy="0." ixz="0." iyy="0." iyz="0." izz="0."/>
    </inertial>
  </link>
  <link name="robot_base_logo_front">
    <inertial>
      <origin xyz="0. 0. 0." rpy="0. 0. 0."/>
      <mass value="0.000001"/>
      <inertia ixx="0." ixy="0." ixz="0." iyy="0." iyz="0." izz="0."/>
    </inertial>
    <visual>
      <origin xyz="0. 0. 0." rpy="0. 0. 0."/>
      <geometry>
        <mesh filename="package://robot_description/meshes/robot_base_logo_front_visuals.obj" scale="1. 1. 1."/>
      </geometry>
    </visual>
  </link>
  <link name="robot_base_logo_left">
    <inertial>
      <origin xyz="0. 0. 0." rpy="0. 0. 0."/>
      <mass value="0.000001"/>
      <inertia ixx="0." ixy="0." ixz="0." iyy="0." iyz="0." izz="0."/>
    </inertial>
    <visual>
      <origin xyz="0. 0. 0." rpy="0. 0. 0."/>
      <geometry>
        <mesh filename="package://robot_description/meshes/robot_base_logo_left_visuals.obj" scale="1. 1. 1."/>
      </geometry>
    </visual>
  </link>
  <link name="robot_base_logo_rear">
    <inertial>
      <origin xyz="0. 0. 0." rpy="0. 0. 0."/>
      <mass value="0.000001"/>
      <inertia ixx="0." ixy="0." ixz="0." iyy="0." iyz="0." izz="0."/>
    </inertial>
    <visual>
      <origin xyz="0. 0. 0." rpy="0. 0. 0."/>
      <geometry>
        <mesh filename="package://robot_description/meshes/robot_base_logo_rear_visuals.obj" scale="1. 1. 1."/>
      </geometry>
    </visual>
  </link>
  <link name="robot_base_logo_right">
    <inertial>
      <origin xyz="0. 0. 0." rpy="0. 0. 0."/>
      <mass value="0.000001"/>
      <inertia ixx="0." ixy="0." ixz="0." iyy="0." iyz="0." izz="0."/>
    </inertial>
    <visual>
      <origin xyz="0. 0. 0." rpy="0. 0. 0."/>
      <geometry>
        <mesh filename="package://robot_description/meshes/robot_base_logo_right_visuals.obj" scale="1. 1. 1."/>
      </geometry>
    </visual>
  </link>
  <link name="robot_front_laser_base_link">
    <inertial>
      <origin xyz="0. 0. 0." rpy="0. 0. 0."/>
      <mass value="0.000001"/>
      <inertia ixx="0." ixy="0." ixz="0." iyy="0." iyz="0." izz="0."/>
    </inertial>
    <visual>
      <origin xyz="-0.07 0. -0.01538" rpy="-3.1415927 0. 0. "/>
      <geometry>
        <box size="0.28321 0.07839 0.02964"/>
      </geometry>
    </visual>
  </link>
  <link name="robot_front_laser_body_link">
    <inertial>
      <origin xyz="0. 0. 0." rpy="0. 0. 0."/>
      <mass value="1.53"/>
      <inertia ixx="0." ixy="0." ixz="0." iyy="0." iyz="0." izz="0."/>
    </inertial>
    <visual>
      <origin xyz="0. 0. 0." rpy="0. 0. -3.1415925"/>
      <geometry>
        <mesh filename="package://robot_description/meshes/robot_front_laser_body_link_visuals.obj" scale="1. 1. 1."/>
      </geometry>
    </visual>
    <collision>
      <origin xyz="0. 0. 0." rpy="0. 0. -3.1415925"/>
      <geometry>
        <mesh filename="package://robot_description/meshes/robot_front_laser_body_link_visuals.obj" scale="1. 1. 1."/>
      </geometry>
    </collision>
  </link>
  <link name="robot_front_laser_link">
    <inertial>
      <origin xyz="0. 0. 0." rpy="0. 0. 0."/>
      <mass value="0.000001"/>
      <inertia ixx="0." ixy="0." ixz="0." iyy="0." iyz="0." izz="0."/>
    </inertial>
  </link>
  <link name="robot_front_left_pole_link">
    <inertial>
      <origin xyz="0. 0. 0." rpy="0. 0. 0."/>
      <mass value="0.000001"/>
      <inertia ixx="0." ixy="0." ixz="0." iyy="0." iyz="0." izz="0."/>
    </inertial>
    <visual>
      <origin xyz="0. 0. 0." rpy="0. 0. 0."/>
      <geometry>
        <mesh filename="package://robot_description/meshes/robot_front_left_pole_link_visuals.obj" scale="1. 1. 1."/>
      </geometry>
    </visual>
    <collision>
      <origin xyz="0. 0. 0." rpy="0. 0. 0."/>
      <geometry>
        <mesh filename="package://robot_description/meshes/robot_front_left_pole_link_visuals.obj" scale="1. 1. 1."/>
      </geometry>
    </collision>
  </link>
  <link name="robot_front_left_pole_sup_link">
    <inertial>
      <origin xyz="0. 0. 0." rpy="0. 0. 0."/>
      <mass value="0.000001"/>
      <inertia ixx="0." ixy="0." ixz="0." iyy="0." iyz="0." izz="0."/>
    </inertial>
    <visual>
      <origin xyz="0. 0. 0.03" rpy="0. 0. 0."/>
      <geometry>
        <mesh filename="package://robot_description/meshes/robot_front_left_pole_sup_link_visuals.obj" scale="1. 1. 1."/>
      </geometry>
    </visual>
    <collision>
      <origin xyz="0. 0. 0.03" rpy="0. 0. 0."/>
      <geometry>
        <mesh filename="package://robot_description/meshes/robot_front_left_pole_sup_link_visuals.obj" scale="1. 1. 1."/>
      </geometry>
    </collision>
  </link>
  <link name="robot_front_left_rgb_camera_1_link">
    <inertial>
      <origin xyz="0. 0. 0." rpy="0. 0. 0."/>
      <mass value="0.000001"/>
      <inertia ixx="0." ixy="0." ixz="0." iyy="0." iyz="0." izz="0."/>
    </inertial>
    <visual>
      <origin xyz="0. 0. 0." rpy="0. 0. 0."/>
      <geometry>
        <mesh filename="package://robot_description/meshes/robot_front_left_rgb_camera_1_link_visuals.obj" scale="1. 1. 1."/>
      </geometry>
    </visual>
    <collision>
      <origin xyz="0. 0. 0." rpy="0. 0. 0."/>
      <geometry>
        <mesh filename="package://robot_description/meshes/robot_front_left_rgb_camera_1_link_visuals.obj" scale="1. 1. 1."/>
      </geometry>
    </collision>
  </link>
  <link name="robot_front_left_rgb_camera_1_optical_frame">
    <inertial>
      <origin xyz="0. 0. 0." rpy="0. 0. 0."/>
      <mass value="0.000001"/>
      <inertia ixx="0." ixy="0." ixz="0." iyy="0." iyz="0." izz="0."/>
    </inertial>
  </link>
  <link name="robot_front_left_rgb_camera_2_link">
    <inertial>
      <origin xyz="0. 0. 0." rpy="0. 0. 0."/>
      <mass value="0.000001"/>
      <inertia ixx="0." ixy="0." ixz="0." iyy="0." iyz="0." izz="0."/>
    </inertial>
    <visual>
      <origin xyz="0. 0. 0." rpy="0. 0. 0."/>
      <geometry>
        <mesh filename="package://robot_description/meshes/robot_front_left_rgb_camera_2_link_visuals.obj" scale="1. 1. 1."/>
      </geometry>
    </visual>
    <collision>
      <origin xyz="0. 0. 0." rpy="0. 0. 0."/>
      <geometry>
        <mesh filename="package://robot_description/meshes/robot_front_left_rgb_camera_2_link_visuals.obj" scale="1. 1. 1."/>
      </geometry>
    </collision>
  </link>
  <link name="robot_front_left_rgb_camera_2_optical_frame">
    <inertial>
      <origin xyz="0. 0. 0." rpy="0. 0. 0."/>
      <mass value="0.000001"/>
      <inertia ixx="0." ixy="0." ixz="0." iyy="0." iyz="0." izz="0."/>
    </inertial>
  </link>
  <link name="robot_front_rgbd_camera_base_link">
    <inertial>
      <origin xyz="0. 0. 0." rpy="0. 0. 0."/>
      <mass value="0.000001"/>
      <inertia ixx="0." ixy="0." ixz="0." iyy="0." iyz="0." izz="0."/>
    </inertial>
  </link>
  <link name="robot_front_rgbd_camera_color_frame">
    <inertial>
      <origin xyz="0. 0. 0." rpy="0. 0. 0."/>
      <mass value="0.000001"/>
      <inertia ixx="0." ixy="0." ixz="0." iyy="0." iyz="0." izz="0."/>
    </inertial>
  </link>
  <link name="robot_front_rgbd_camera_color_optical_frame">
    <inertial>
      <origin xyz="0. 0. 0." rpy="0. 0. 0."/>
      <mass value="0.000001"/>
      <inertia ixx="0." ixy="0." ixz="0." iyy="0." iyz="0." izz="0."/>
    </inertial>
  </link>
  <link name="robot_front_rgbd_camera_depth_frame">
    <inertial>
      <origin xyz="0. 0. 0." rpy="0. 0. 0."/>
      <mass value="0.000001"/>
      <inertia ixx="0." ixy="0." ixz="0." iyy="0." iyz="0." izz="0."/>
    </inertial>
  </link>
  <link name="robot_front_rgbd_camera_depth_optical_frame">
    <inertial>
      <origin xyz="0. 0. 0." rpy="0. 0. 0."/>
      <mass value="0.000001"/>
      <inertia ixx="0." ixy="0." ixz="0." iyy="0." iyz="0." izz="0."/>
    </inertial>
  </link>
  <link name="robot_front_rgbd_camera_infra1_frame">
    <inertial>
      <origin xyz="0. 0. 0." rpy="0. 0. 0."/>
      <mass value="0.000001"/>
      <inertia ixx="0." ixy="0." ixz="0." iyy="0." iyz="0." izz="0."/>
    </inertial>
  </link>
  <link name="robot_front_rgbd_camera_infra1_optical_frame">
    <inertial>
      <origin xyz="0. 0. 0." rpy="0. 0. 0."/>
      <mass value="0.000001"/>
      <inertia ixx="0." ixy="0." ixz="0." iyy="0." iyz="0." izz="0."/>
    </inertial>
  </link>
  <link name="robot_front_rgbd_camera_infra2_frame">
    <inertial>
      <origin xyz="0. 0. 0." rpy="0. 0. 0."/>
      <mass value="0.000001"/>
      <inertia ixx="0." ixy="0." ixz="0." iyy="0." iyz="0." izz="0."/>
    </inertial>
  </link>
  <link name="robot_front_rgbd_camera_infra2_optical_frame">
    <inertial>
      <origin xyz="0. 0. 0." rpy="0. 0. 0."/>
      <mass value="0.000001"/>
      <inertia ixx="0." ixy="0." ixz="0." iyy="0." iyz="0." izz="0."/>
    </inertial>
  </link>
  <link name="robot_front_rgbd_camera_link">
    <inertial>
      <origin xyz="0. 0. 0." rpy="0. 0. 0."/>
      <mass value="0.1"/>
      <inertia ixx="0." ixy="0." ixz="0." iyy="0." iyz="0." izz="0."/>
    </inertial>
    <visual>
      <origin xyz="0.0149 -0.0175 0. " rpy="1.5707964 -0. 1.5707964"/>
      <geometry>
        <mesh filename="package://robot_description/meshes/robot_front_rgbd_camera_link_visuals.obj" scale="1. 1. 1."/>
      </geometry>
    </visual>
  </link>
  <link name="robot_front_right_pole_link">
    <inertial>
      <origin xyz="0. 0. 0." rpy="0. 0. 0."/>
      <mass value="0.000001"/>
      <inertia ixx="0." ixy="0." ixz="0." iyy="0." iyz="0." izz="0."/>
    </inertial>
    <visual>
      <origin xyz="0. 0. 0." rpy="0. 0. 0."/>
      <geometry>
        <mesh filename="package://robot_description/meshes/robot_front_right_pole_link_visuals.obj" scale="1. 1. 1."/>
      </geometry>
    </visual>
    <collision>
      <origin xyz="0. 0. 0." rpy="0. 0. 0."/>
      <geometry>
        <mesh filename="package://robot_description/meshes/robot_front_right_pole_link_visuals.obj" scale="1. 1. 1."/>
      </geometry>
    </collision>
  </link>
  <link name="robot_front_right_pole_sup_link">
    <inertial>
      <origin xyz="0. 0. 0." rpy="0. 0. 0."/>
      <mass value="0.000001"/>
      <inertia ixx="0." ixy="0." ixz="0." iyy="0." iyz="0." izz="0."/>
    </inertial>
    <visual>
      <origin xyz="0. 0. 0." rpy="0. 0. 0."/>
      <geometry>
        <mesh filename="package://robot_description/meshes/robot_front_right_pole_sup_link_visuals.obj" scale="1. 1. 1."/>
      </geometry>
    </visual>
    <collision>
      <origin xyz="0. 0. 0." rpy="0. 0. 0."/>
      <geometry>
        <mesh filename="package://robot_description/meshes/robot_front_right_pole_sup_link_visuals.obj" scale="1. 1. 1."/>
      </geometry>
    </collision>
  </link>
  <link name="robot_imu_link">
    <inertial>
      <origin xyz="0. 0. 0." rpy="0. 0. 0."/>
      <mass value="0.05"/>
      <inertia ixx="0." ixy="0." ixz="0." iyy="0." iyz="0." izz="0."/>
    </inertial>
    <visual>
      <origin xyz="0. 0. 0." rpy="0. 0. 0."/>
      <geometry>
        <box size="0.001 0.001 0.001"/>
      </geometry>
    </visual>
  </link>
  <link name="robot_pantilt_base_link">
    <inertial>
      <origin xyz="0. 0. 0." rpy="0. 0. 0."/>
      <mass value="0.005"/>
      <inertia ixx="0." ixy="0." ixz="0." iyy="0." iyz="0." izz="0."/>
    </inertial>
    <visual>
      <origin xyz="0. 0. 0." rpy="0. 0. 0."/>
      <geometry>
        <box size="0.01 0.01 0.01"/>
      </geometry>
    </visual>
  </link>
  <link name="robot_pantilt_pan_link">
    <inertial>
      <origin xyz="0. 0. 0." rpy="0. 0. 0."/>
      <mass value="1."/>
      <inertia ixx="0." ixy="0." ixz="0." iyy="0." iyz="0." izz="0."/>
    </inertial>
    <visual>
      <origin xyz="0. 0. 0." rpy="0. 0. 0."/>
      <geometry>
        <mesh filename="package://robot_description/meshes/robot_pantilt_pan_link_visuals.obj" scale="1. 1. 1."/>
      </geometry>
    </visual>
    <collision>
      <origin xyz="0. 0. 0." rpy="0. 0. 0."/>
      <geometry>
        <mesh filename="package://robot_description/meshes/robot_pantilt_pan_link_visuals.obj" scale="1. 1. 1."/>
      </geometry>
    </collision>
  </link>
  <link name="robot_pantilt_tilt_link">
    <inertial>
      <origin xyz="0. 0. 0." rpy="0. 0. 0."/>
      <mass value="1."/>
      <inertia ixx="0." ixy="0." ixz="0." iyy="0." iyz="0." izz="0."/>
    </inertial>
    <visual>
      <origin xyz="0. 0. 0." rpy="0. 0. 0."/>
      <geometry>
        <mesh filename="package://robot_description/meshes/robot_pantilt_tilt_link_visuals.obj" scale="1. 1. 1."/>
      </geometry>
    </visual>
  </link>
  <link name="robot_rear_laser_base_link">
    <inertial>
      <origin xyz="0. 0. 0." rpy="0. 0. 0."/>
      <mass value="0.000001"/>
      <inertia ixx="0." ixy="0." ixz="0." iyy="0." iyz="0." izz="0."/>
    </inertial>
    <visual>
      <origin xyz="-0.07 0. -0.01538" rpy="3.1415927 0. 0. "/>
      <geometry>
        <box size="0.28321 0.07839 0.02964"/>
      </geometry>
    </visual>
  </link>
  <link name="robot_rear_laser_body_link">
    <inertial>
      <origin xyz="0. 0. 0." rpy="0. 0. 0."/>
      <mass value="1.53"/>
      <inertia ixx="0." ixy="0." ixz="0." iyy="0." iyz="0." izz="0."/>
    </inertial>
    <visual>
      <origin xyz="0. 0. 0." rpy="0. 0. -3.1415925"/>
      <geometry>
        <mesh filename="package://robot_description/meshes/robot_rear_laser_body_link_visuals.obj" scale="1. 1. 1."/>
      </geometry>
    </visual>
    <collision>
      <origin xyz="0. 0. 0." rpy="0. 0. -3.1415925"/>
      <geometry>
        <mesh filename="package://robot_description/meshes/robot_rear_laser_body_link_visuals.obj" scale="1. 1. 1."/>
      </geometry>
    </collision>
  </link>
  <link name="robot_rear_laser_link">
    <inertial>
      <origin xyz="0. 0. 0." rpy="0. 0. 0."/>
      <mass value="0.000001"/>
      <inertia ixx="0." ixy="0." ixz="0." iyy="0." iyz="0." izz="0."/>
    </inertial>
  </link>
  <link name="robot_top_right_rgbd_camera_1_camera_body">
    <inertial>
      <origin xyz="0. 0. 0." rpy="0. 0. 0."/>
      <mass value="0.000001"/>
      <inertia ixx="0." ixy="0." ixz="0." iyy="0." iyz="0." izz="0."/>
    </inertial>
    <visual>
      <origin xyz="0. 0. 0." rpy="0. 0. 0."/>
      <geometry>
        <box size="0.0994 0.0996 0.023 "/>
      </geometry>
    </visual>
  </link>
  <link name="robot_top_right_rgbd_camera_1_camera_visor">
    <inertial>
      <origin xyz="0. 0. 0." rpy="0. 0. 0."/>
      <mass value="0.000001"/>
      <inertia ixx="0." ixy="0." ixz="0." iyy="0." iyz="0." izz="0."/>
    </inertial>
    <visual>
      <origin xyz="-0.0128 0. 0. " rpy="0. 0. 0."/>
      <geometry>
        <box size="0.026 0.101 0.037"/>
      </geometry>
    </visual>
  </link>
  <link name="robot_top_right_rgbd_camera_1_link">
    <inertial>
      <origin xyz="0. 0. 0." rpy="0. 0. 0."/>
      <mass value="0.000001"/>
      <inertia ixx="0." ixy="0." ixz="0." iyy="0." iyz="0." izz="0."/>
    </inertial>
    <visual>
      <origin xyz="-0.013 0. 0. " rpy="0. 0. 0."/>
      <geometry>
        <box size="0.026 0.103 0.039"/>
      </geometry>
    </visual>
  </link>
  <link name="robot_top_right_rgbd_camera_2_camera_body">
    <inertial>
      <origin xyz="0. 0. 0." rpy="0. 0. 0."/>
      <mass value="0.000001"/>
      <inertia ixx="0." ixy="0." ixz="0." iyy="0." iyz="0." izz="0."/>
    </inertial>
    <visual>
      <origin xyz="0. 0. 0." rpy="0. 0. 0."/>
      <geometry>
        <box size="0.0994 0.0996 0.023 "/>
      </geometry>
    </visual>
  </link>
  <link name="robot_top_right_rgbd_camera_2_camera_visor">
    <inertial>
      <origin xyz="0. 0. 0." rpy="0. 0. 0."/>
      <mass value="0.000001"/>
      <inertia ixx="0." ixy="0." ixz="0." iyy="0." iyz="0." izz="0."/>
    </inertial>
    <visual>
      <origin xyz="-0.0128 0. 0. " rpy="0. 0. 0."/>
      <geometry>
        <box size="0.026 0.101 0.037"/>
      </geometry>
    </visual>
  </link>
  <link name="robot_top_right_rgbd_camera_2_link">
    <inertial>
      <origin xyz="0. 0. 0." rpy="0. 0. 0."/>
      <mass value="0.000001"/>
      <inertia ixx="0." ixy="0." ixz="0." iyy="0." iyz="0." izz="0."/>
    </inertial>
    <visual>
      <origin xyz="-0.013 0. 0. " rpy="0. 0. 0."/>
      <geometry>
        <box size="0.026 0.103 0.039"/>
      </geometry>
    </visual>
  </link>
  <link name="summit_xl_back_left_wheel_link">
    <inertial>
      <origin xyz="0. 0. 0." rpy="0. 0. 0."/>
      <mass value="6.5"/>
      <inertia ixx="0." ixy="0." ixz="0." iyy="0." iyz="0." izz="0."/>
    </inertial>
    <visual>
      <origin xyz="0. 0. 0." rpy="0. 0. 0."/>
      <geometry>
        <mesh filename="package://robot_description/meshes/summit_xl_back_left_wheel_link_visuals.obj" scale="1. 1. 1."/>
      </geometry>
    </visual>
    <visual>
      <origin xyz="0. 0. 0." rpy="1.5707964 0. 0. "/>
      <geometry>
        <cylinder radius="0.115" length="0.06"/>
      </geometry>
    </visual>
    <collision>
      <origin xyz="0. 0. 0." rpy="1.5707964 0. 0. "/>
      <geometry>
        <cylinder radius="0.115" length="0.06"/>
      </geometry>
    </collision>
  </link>
  <link name="summit_xl_back_right_wheel_link">
    <inertial>
      <origin xyz="0. 0. 0." rpy="0. 0. 0."/>
      <mass value="6.5"/>
      <inertia ixx="0." ixy="0." ixz="0." iyy="0." iyz="0." izz="0."/>
    </inertial>
    <visual>
      <origin xyz="0. 0. 0." rpy="0. 0. 0."/>
      <geometry>
        <mesh filename="package://robot_description/meshes/summit_xl_back_right_wheel_link_visuals.obj" scale="1. 1. 1."/>
      </geometry>
    </visual>
    <visual>
      <origin xyz="0. 0. 0." rpy="1.5707964 0. 0. "/>
      <geometry>
        <cylinder radius="0.115" length="0.06"/>
      </geometry>
    </visual>
    <collision>
      <origin xyz="0. 0. 0." rpy="1.5707964 0. 0. "/>
      <geometry>
        <cylinder radius="0.115" length="0.06"/>
      </geometry>
    </collision>
  </link>
  <link name="summit_xl_front_left_wheel_link">
    <inertial>
      <origin xyz="0. 0. 0." rpy="0. 0. 0."/>
      <mass value="6.5"/>
      <inertia ixx="0." ixy="0." ixz="0." iyy="0." iyz="0." izz="0."/>
    </inertial>
    <visual>
      <origin xyz="0. 0. 0." rpy="0. 0. 0."/>
      <geometry>
        <mesh filename="package://robot_description/meshes/summit_xl_front_left_wheel_link_visuals.obj" scale="1. 1. 1."/>
      </geometry>
    </visual>
    <visual>
      <origin xyz="0. 0. 0." rpy="1.5707964 0. 0. "/>
      <geometry>
        <cylinder radius="0.115" length="0.06"/>
      </geometry>
    </visual>
    <collision>
      <origin xyz="0. 0. 0." rpy="1.5707964 0. 0. "/>
      <geometry>
        <cylinder radius="0.115" length="0.06"/>
      </geometry>
    </collision>
  </link>
  <link name="summit_xl_front_right_wheel_link">
    <inertial>
      <origin xyz="0. 0. 0." rpy="0. 0. 0."/>
      <mass value="6.5"/>
      <inertia ixx="0." ixy="0." ixz="0." iyy="0." iyz="0." izz="0."/>
    </inertial>
    <visual>
      <origin xyz="0. 0. 0." rpy="0. 0. 0."/>
      <geometry>
        <mesh filename="package://robot_description/meshes/summit_xl_front_right_wheel_link_visuals.obj" scale="1. 1. 1."/>
      </geometry>
    </visual>
    <visual>
      <origin xyz="0. 0. 0." rpy="1.5707964 0. 0. "/>
      <geometry>
        <cylinder radius="0.115" length="0.06"/>
      </geometry>
    </visual>
    <collision>
      <origin xyz="0. 0. 0." rpy="1.5707964 0. 0. "/>
      <geometry>
        <cylinder radius="0.115" length="0.06"/>
      </geometry>
    </collision>
  </link>
</robot>
